Workbook

Sheet Sheet1
A1: Partido | B1: Q15_1 | C1: Q15_X | D1: Q15_2 | E1: LAE_1 | F1: LAE_X | G1: LAE_2 | H1: APU_1 | I1: APU_X | J1: APU_2 | K1: MEDIA_1 | L1: MEDIA_X | M1: MEDIA_2 | N1: N_1 | O1: N_X | P1: N_2 | Q1: 32 | R1: unos | S1: equises | T1: doses
A2: 1 | B2: 50 | C2: 28 | D2: 22 | E2: 50 | F2: 28 | G2: 22 | H2: 52 | I2: 27 | J2: 21 | K2: =AVERAGE(B2,E2,H2) -> 50.666667 | L2: =AVERAGE(C2,F2,I2) -> 27.666667 | M2: =AVERAGE(D2,G2,J2) -> 21.666667 | N2: =ROUND($Q$1*K2/SUM($K2:$M2),0) -> 16 | O2: =ROUND($Q$1*L2/SUM($K2:$M2),0) -> 9 | P2: =ROUND($Q$1*M2/SUM($K2:$M2),0) -> 7 | Q2: =N2+O2+P2 -> 32 | R2: 16 | S2: 9 | T2: 7 | U2: =R2+S2+T2 -> 32 | V2: =K2/R2 -> 3.1666667 | W2: =L2/S2 -> 3.0740741 | X2: =M2/T2 -> 3.0952381 | Y2: =AVERAGE(V2:X2) -> 3.1119929
A3: 2 | B3: 33 | C3: 46 | D3: 21 | E3: 30 | F3: 19 | G3: 51 | H3: 48 | I3: 27 | J3: 24 | K3: =AVERAGE(B3,E3,H3) -> 37 | L3: =AVERAGE(C3,F3,I3) -> 30.666667 | M3: =AVERAGE(D3,G3,J3) -> 32 | N3: =ROUND($Q$1*K3/SUM($K3:$M3),0) -> 12 | O3: =ROUND($Q$1*L3/SUM($K3:$M3),0) -> 10 | P3: =ROUND($Q$1*M3/SUM($K3:$M3),0) -> 10 | Q3: =N3+O3+P3 -> 32 | R3: 12 | S3: 10 | T3: 10 | U3: =R3+S3+T3 -> 32 | V3: =K3/R3 -> 3.0833333 | W3: =L3/S3 -> 3.0666667 | X3: =M3/T3 -> 3.2 | Y3: =AVERAGE(V3:X3) -> 3.1166667
A4: 3 | B4: 15 | C4: 39 | D4: 46 | E4: 33 | F4: 23 | G4: 44 | H4: 29 | I4: 31 | J4: 40 | K4: =AVERAGE(B4,E4,H4) -> 25.666667 | L4: =AVERAGE(C4,F4,I4) -> 31 | M4: =AVERAGE(D4,G4,J4) -> 43.333333 | N4: =ROUND($Q$1*K4/SUM($K4:$M4),0) -> 8 | O4: =ROUND($Q$1*L4/SUM($K4:$M4),0) -> 10 | P4: =ROUND($Q$1*M4/SUM($K4:$M4),0) -> 14 | Q4: =N4+O4+P4 -> 32 | R4: 8 | S4: 10 | T4: 14 | U4: =R4+S4+T4 -> 32 | V4: =K4/R4 -> 3.2083333 | W4: =L4/S4 -> 3.1 | X4: =M4/T4 -> 3.0952381 | Y4: =AVERAGE(V4:X4) -> 3.1345238
A5: 4 | B5: 63 | C5: 17 | D5: 20 | E5: 48 | F5: 28 | G5: 24 | H5: 81 | I5: 14 | J5: 5 | K5: =AVERAGE(B5,E5,H5) -> 64 | L5: =AVERAGE(C5,F5,I5) -> 19.666667 | M5: =AVERAGE(D5,G5,J5) -> 16.333333 | N5: =ROUND($Q$1*K5/SUM($K5:$M5),0) -> 20 | O5: =ROUND($Q$1*L5/SUM($K5:$M5),0) -> 6 | P5: =ROUND($Q$1*M5/SUM($K5:$M5),0) -> 5 | Q5: =N5+O5+P5 -> 31 | R5: 20 | S5: 7 | T5: 5 | U5: =R5+S5+T5 -> 32 | V5: =K5/R5 -> 3.2 | W5: =L5/S5 -> 2.8095238 | X5: =M5/T5 -> 3.2666667 | Y5: =AVERAGE(V5:X5) -> 3.0920635
A6: 5 | B6: 55 | C6: 29 | D6: 16 | E6: 33 | F6: 22 | G6: 45 | H6: 62 | I6: 25 | J6: 13 | K6: =AVERAGE(B6,E6,H6) -> 50 | L6: =AVERAGE(C6,F6,I6) -> 25.333333 | M6: =AVERAGE(D6,G6,J6) -> 24.666667 | N6: =ROUND($Q$1*K6/SUM($K6:$M6),0) -> 16 | O6: =ROUND($Q$1*L6/SUM($K6:$M6),0) -> 8 | P6: =ROUND($Q$1*M6/SUM($K6:$M6),0) -> 8 | Q6: =N6+O6+P6 -> 32 | R6: 16 | S6: 8 | T6: 8 | U6: =R6+S6+T6 -> 32 | V6: =K6/R6 -> 3.125 | W6: =L6/S6 -> 3.1666667 | X6: =M6/T6 -> 3.0833333 | Y6: =AVERAGE(V6:X6) -> 3.125
A7: 6 | B7: 52 | C7: 26 | D7: 22 | E7: 58 | F7: 23 | G7: 19 | H7: 42 | I7: 28 | J7: 31 | K7: =AVERAGE(B7,E7,H7) -> 50.666667 | L7: =AVERAGE(C7,F7,I7) -> 25.666667 | M7: =AVERAGE(D7,G7,J7) -> 24 | N7: =ROUND($Q$1*K7/SUM($K7:$M7),0) -> 16 | O7: =ROUND($Q$1*L7/SUM($K7:$M7),0) -> 8 | P7: =ROUND($Q$1*M7/SUM($K7:$M7),0) -> 8 | Q7: =N7+O7+P7 -> 32 | R7: 16 | S7: 8 | T7: 8 | U7: =R7+S7+T7 -> 32 | V7: =K7/R7 -> 3.1666667 | W7: =L7/S7 -> 3.2083333 | X7: =M7/T7 -> 3 | Y7: =AVERAGE(V7:X7) -> 3.125
A8: 7 | B8: 41 | C8: 36 | D8: 23 | E8: 47 | F8: 29 | G8: 24 | H8: 57 | I8: 24 | J8: 19 | K8: =AVERAGE(B8,E8,H8) -> 48.333333 | L8: =AVERAGE(C8,F8,I8) -> 29.666667 | M8: =AVERAGE(D8,G8,J8) -> 22 | N8: =ROUND($Q$1*K8/SUM($K8:$M8),0) -> 15 | O8: =ROUND($Q$1*L8/SUM($K8:$M8),0) -> 9 | P8: =ROUND($Q$1*M8/SUM($K8:$M8),0) -> 7 | Q8: =N8+O8+P8 -> 31 | R8: 15 | S8: 10 | T8: 7 | U8: =R8+S8+T8 -> 32 | V8: =K8/R8 -> 3.2222222 | W8: =L8/S8 -> 2.9666667 | X8: =M8/T8 -> 3.1428571 | Y8: =AVERAGE(V8:X8) -> 3.110582
A9: 8 | B9: 18 | C9: 18 | D9: 65 | E9: 51 | F9: 24 | G9: 25 | H9: 28 | I9: 26 | J9: 46 | K9: =AVERAGE(B9,E9,H9) -> 32.333333 | L9: =AVERAGE(C9,F9,I9) -> 22.666667 | M9: =AVERAGE(D9,G9,J9) -> 45.333333 | N9: =ROUND($Q$1*K9/SUM($K9:$M9),0) -> 10 | O9: =ROUND($Q$1*L9/SUM($K9:$M9),0) -> 7 | P9: =ROUND($Q$1*M9/SUM($K9:$M9),0) -> 14 | Q9: =N9+O9+P9 -> 31 | R9: 10 | S9: 8 | T9: 14 | U9: =R9+S9+T9 -> 32 | V9: =K9/R9 -> 3.2333333 | W9: =L9/S9 -> 2.8333333 | X9: =M9/T9 -> 3.2380952 | Y9: =AVERAGE(V9:X9) -> 3.1015873
A10: 9 | B10: 64 | C10: 18 | D10: 18 | E10: 33 | F10: 20 | G10: 47 | H10: 71 | I10: 19 | J10: 10 | K10: =AVERAGE(B10,E10,H10) -> 56 | L10: =AVERAGE(C10,F10,I10) -> 19 | M10: =AVERAGE(D10,G10,J10) -> 25 | N10: =ROUND($Q$1*K10/SUM($K10:$M10),0) -> 18 | O10: =ROUND($Q$1*L10/SUM($K10:$M10),0) -> 6 | P10: =ROUND($Q$1*M10/SUM($K10:$M10),0) -> 8 | Q10: =N10+O10+P10 -> 32 | R10: 18 | S10: 6 | T10: 8 | U10: =R10+S10+T10 -> 32 | V10: =K10/R10 -> 3.1111111 | W10: =L10/S10 -> 3.1666667 | X10: =M10/T10 -> 3.125 | Y10: =AVERAGE(V10:X10) -> 3.1342593
A11: 10 | B11: 36 | C11: 39 | D11: 25 | E11: 29 | F11: 18 | G11: 53 | H11: 56 | I11: 24 | J11: 20 | K11: =AVERAGE(B11,E11,H11) -> 40.333333 | L11: =AVERAGE(C11,F11,I11) -> 27 | M11: =AVERAGE(D11,G11,J11) -> 32.666667 | N11: =ROUND($Q$1*K11/SUM($K11:$M11),0) -> 13 | O11: =ROUND($Q$1*L11/SUM($K11:$M11),0) -> 9 | P11: =ROUND($Q$1*M11/SUM($K11:$M11),0) -> 10 | Q11: =N11+O11+P11 -> 32 | R11: 13 | S11: 9 | T11: 10 | U11: =R11+S11+T11 -> 32 | V11: =K11/R11 -> 3.1025641 | W11: =L11/S11 -> 3 | X11: =M11/T11 -> 3.2666667 | Y11: =AVERAGE(V11:X11) -> 3.1230769
A12: 11 | B12: 28 | C12: 49 | D12: 23 | E12: 50 | F12: 27 | G12: 23 | H12: 35 | I12: 27 | J12: 37 | K12: =AVERAGE(B12,E12,H12) -> 37.666667 | L12: =AVERAGE(C12,F12,I12) -> 34.333333 | M12: =AVERAGE(D12,G12,J12) -> 27.666667 | N12: =ROUND($Q$1*K12/SUM($K12:$M12),0) -> 12 | O12: =ROUND($Q$1*L12/SUM($K12:$M12),0) -> 11 | P12: =ROUND($Q$1*M12/SUM($K12:$M12),0) -> 9 | Q12: =N12+O12+P12 -> 32 | R12: 12 | S12: 11 | T12: 9 | U12: =R12+S12+T12 -> 32 | V12: =K12/R12 -> 3.1388889 | W12: =L12/S12 -> 3.1212121 | X12: =M12/T12 -> 3.0740741 | Y12: =AVERAGE(V12:X12) -> 3.1113917
A13: 12 | B13: 20 | C13: 37 | D13: 43 | E13: 28 | F13: 27 | G13: 45 | H13: 30 | I13: 26 | J13: 43 | K13: =AVERAGE(B13,E13,H13) -> 26 | L13: =AVERAGE(C13,F13,I13) -> 30 | M13: =AVERAGE(D13,G13,J13) -> 43.666667 | N13: =ROUND($Q$1*K13/SUM($K13:$M13),0) -> 8 | O13: =ROUND($Q$1*L13/SUM($K13:$M13),0) -> 10 | P13: =ROUND($Q$1*M13/SUM($K13:$M13),0) -> 14 | Q13: =N13+O13+P13 -> 32 | R13: 8 | S13: 10 | T13: 14 | U13: =R13+S13+T13 -> 32 | V13: =K13/R13 -> 3.25 | W13: =L13/S13 -> 3 | X13: =M13/T13 -> 3.1190476 | Y13: =AVERAGE(V13:X13) -> 3.1230159
... A15: 14 | B15: 69 | C15: 17 | D15: 14 | E15: 31 | F15: 17 | G15: 52 | H15: 62 | I15: 21 | J15: 17 | K15: =AVERAGE(B15,E15,H15) -> 54 | L15: =AVERAGE(C15,F15,I15) -> 18.333333 | M15: =AVERAGE(D15,G15,J15) -> 27.666667 | N15: =ROUND($Q$1*K15/SUM($K15:$M15),0) -> 17 | O15: =ROUND($Q$1*L15/SUM($K15:$M15),0) -> 6 | P15: =ROUND($Q$1*M15/SUM($K15:$M15),0) -> 9 | Q15: =N15+O15+P15 -> 32 | R15: 17 | S15: 6 | T15: 9 | U15: =R15+S15+T15 -> 32 | V15: =K15/R15 -> 3.1764706 | W15: =L15/S15 -> 3.0555556 | X15: =M15/T15 -> 3.0740741 | Y15: =AVERAGE(V15:X15) -> 3.1020334
A18: {'1': | B18: , 'X': | C18: , '2': | D18: }, | K18: Ap base | L18: =CONCATENATE("['",L19,"','",L20,"','",L21,"','",L22,"','",L23,"','",L24,"','",L25,"','",L26,"','",L27,"','",L28,"','",L29,"','",L30,"','",L31,"','",L32,"']") -> ['1','1','2','1','1','1','1','2','1','1','1','2','1','1'] | Q18: =Q$1 -> 32 | R18: =Q18*100/Q$1 -> 100
A19: 1 | B19: =CONCATENATE(A$18,R2,B$18,S2,C$18,T2,D$18) -> {'1':16, 'X':9, '2':7}, | K19: 1 | L19: =IF(K2=MAX(K2:M2),1,IF(L2=MAX(K2:M2),"X",IF(M2=MAX(K2:M2),2))) -> 1 | Q19: =Q$1-1 -> 31 | R19: =Q19*100/Q$1 -> 96.875
A20: 2 | B20: =CONCATENATE(A$18,R3,B$18,S3,C$18,T3,D$18) -> {'1':12, 'X':10, '2':10}, | K20: 2 | L20: =IF(K3=MAX(K3:M3),1,IF(L3=MAX(K3:M3),"X",IF(M3=MAX(K3:M3),2))) -> 1 | Q20: =Q$1-2 -> 30 | R20: =Q20*100/Q$1 -> 93.75
A21: 3 | B21: =CONCATENATE(A$18,R4,B$18,S4,C$18,T4,D$18) -> {'1':8, 'X':10, '2':14}, | K21: 3 | L21: =IF(K4=MAX(K4:M4),1,IF(L4=MAX(K4:M4),"X",IF(M4=MAX(K4:M4),2))) -> 2 | Q21: =Q$1-3 -> 29 | R21: =Q21*100/Q$1 -> 90.625
A22: 4 | B22: =CONCATENATE(A$18,R5,B$18,S5,C$18,T5,D$18) -> {'1':20, 'X':7, '2':5}, | K22: 4 | L22: =IF(K5=MAX(K5:M5),1,IF(L5=MAX(K5:M5),"X",IF(M5=MAX(K5:M5),2))) -> 1 | Q22: =Q$1-4 -> 28 | R22: =Q22*100/Q$1 -> 87.5
A23: 5 | B23: =CONCATENATE(A$18,R6,B$18,S6,C$18,T6,D$18) -> {'1':16, 'X':8, '2':8}, | K23: 5 | L23: =IF(K6=MAX(K6:M6),1,IF(L6=MAX(K6:M6),"X",IF(M6=MAX(K6:M6),2))) -> 1 | Q23: =Q$1-5 -> 27 | R23: =Q23*100/Q$1 -> 84.375
A24: 6 | B24: =CONCATENATE(A$18,R7,B$18,S7,C$18,T7,D$18) -> {'1':16, 'X':8, '2':8}, | K24: 6 | L24: =IF(K7=MAX(K7:M7),1,IF(L7=MAX(K7:M7),"X",IF(M7=MAX(K7:M7),2))) -> 1 | Q24: =Q$1-6 -> 26 | R24: =Q24*100/Q$1 -> 81.25
A25: 7 | B25: =CONCATENATE(A$18,R8,B$18,S8,C$18,T8,D$18) -> {'1':15, 'X':10, '2':7}, | K25: 7 | L25: =IF(K8=MAX(K8:M8),1,IF(L8=MAX(K8:M8),"X",IF(M8=MAX(K8:M8),2))) -> 1 | Q25: =Q$1-7 -> 25 | R25: =Q25*100/Q$1 -> 78.125
A26: 8 | B26: =CONCATENATE(A$18,R9,B$18,S9,C$18,T9,D$18) -> {'1':10, 'X':8, '2':14}, | K26: 8 | L26: =IF(K9=MAX(K9:M9),1,IF(L9=MAX(K9:M9),"X",IF(M9=MAX(K9:M9),2))) -> 2 | Q26: =Q$1-8 -> 24 | R26: =Q26*100/Q$1 -> 75
A27: 9 | B27: =CONCATENATE(A$18,R10,B$18,S10,C$18,T10,D$18) -> {'1':18, 'X':6, '2':8}, | K27: 9 | L27: =IF(K10=MAX(K10:M10),1,IF(L10=MAX(K10:M10),"X",IF(M10=MAX(K10:M10),2))) -> 1 | Q27: =Q$1-9 -> 23 | R27: =Q27*100/Q$1 -> 71.875
A28: 10 | B28: =CONCATENATE(A$18,R11,B$18,S11,C$18,T11,D$18) -> {'1':13, 'X':9, '2':10}, | K28: 10 | L28: =IF(K11=MAX(K11:M11),1,IF(L11=MAX(K11:M11),"X",IF(M11=MAX(K11:M11),2))) -> 1 | Q28: =Q$1-10 -> 22 | R28: =Q28*100/Q$1 -> 68.75
A29: 11 | B29: =CONCATENATE(A$18,R12,B$18,S12,C$18,T12,D$18) -> {'1':12, 'X':11, '2':9}, | K29: 11 | L29: =IF(K12=MAX(K12:M12),1,IF(L12=MAX(K12:M12),"X",IF(M12=MAX(K12:M12),2))) -> 1 | Q29: =Q$1-11 -> 21 | R29: =Q29*100/Q$1 -> 65.625
A30: 12 | B30: =CONCATENATE(A$18,R13,B$18,S13,C$18,T13,D$18) -> {'1':8, 'X':10, '2':14}, | K30: 12 | L30: =IF(K13=MAX(K13:M13),1,IF(L13=MAX(K13:M13),"X",IF(M13=MAX(K13:M13),2))) -> 2 | Q30: =Q$1-12 -> 20 | R30: =Q30*100/Q$1 -> 62.5
A31: 13 | B31: =CONCATENATE(A$18,R14,B$18,S14,C$18,T14,D$18) -> {'1':12, 'X':9, '2':11}, | K31: 13 | L31: =IF(K14=MAX(K14:M14),1,IF(L14=MAX(K14:M14),"X",IF(M14=MAX(K14:M14),2))) -> 1 | Q31: =Q$1-13 -> 19 | R31: =Q31*100/Q$1 -> 59.375
A32: 14 | B32: =CONCATENATE(A$18,R15,B$18,S15,C$18,T15,D$18) -> {'1':17, 'X':6, '2':9}, | K32: 14 | L32: =IF(K15=MAX(K15:M15),1,IF(L15=MAX(K15:M15),"X",IF(M15=MAX(K15:M15),2))) -> 1 | Q32: =Q$1-14 -> 18 | R32: =Q32*100/Q$1 -> 56.25
Q33: =Q$1-15 -> 17 | R33: =Q33*100/Q$1 -> 53.125
Q34: =Q$1-16 -> 16 | R34: =Q34*100/Q$1 -> 50
Q35: =Q$1-17 -> 15 | R35: =Q35*100/Q$1 -> 46.875
Q36: =Q$1-18 -> 14 | R36: =Q36*100/Q$1 -> 43.75
Q37: =Q$1-18 -> 14 | R37: =Q37*100/Q$1 -> 43.75
Q38: =Q$1-19 -> 13 | R38: =Q38*100/Q$1 -> 40.625
Q39: =Q$1-20 -> 12 | R39: =Q39*100/Q$1 -> 37.5
Q40: =Q$1-21 -> 11 | R40: =Q40*100/Q$1 -> 34.375
Q41: =Q$1-22 -> 10 | R41: =Q41*100/Q$1 -> 31.25
Q42: =Q$1-23 -> 9 | R42: =Q42*100/Q$1 -> 28.125
Q43: =Q$1-24 -> 8 | R43: =Q43*100/Q$1 -> 25
...

Sheet Hoja1
B1: 1 | C1: 2 | D1: 3 | E1: 4 | F1: 5 | G1: 6 | H1: 7 | I1: 8 | J1: 9 | K1: 10 | L1: 11 | M1: 12 | N1: 13 | O1: 14 | P1: 15 | Q1: 16
A2: 1 | B2: ['2' | C2: ['1' | D2: ['1' | E2: ['2' | F2: ['X' | G2: ['1' | H2: ['2' | I2: ['1' | J2: ['1' | K2: ['X' | L2: ['1' | M2: ['1' | N2: ['2' | O2: ['X' | P2: ['X' | Q2: ['1'
A3: 2 | B3: 'X' | C3: '1' | D3: '1' | E3: '2' | F3: '1' | G3: 'X' | H3: '1' | I3: 'X' | J3: '1' | K3: 'X' | L3: '1' | M3: '2' | N3: '1' | O3: '2' | P3: '1' | Q3: '1'
A4: 3 | B4: '1' | C4: '1' | D4: 'X' | E4: '1' | F4: '2' | G4: '2' | H4: '2' | I4: '1' | J4: '1' | K4: '1' | L4: 'X' | M4: '2' | N4: 'X' | O4: '1' | P4: '2' | Q4: 'X'
A5: 4 | B5: '2' | C5: '1' | D5: '1' | E5: '2' | F5: '1' | G5: '2' | H5: '1' | I5: '2' | J5: 'X' | K5: '1' | L5: 'X' | M5: '1' | N5: '1' | O5: 'X' | P5: '2' | Q5: 'X'
A6: 5 | B6: '1' | C6: '2' | D6: 'X' | E6: '1' | F6: '1' | G6: '2' | H6: '1' | I6: '2' | J6: 'X' | K6: '1' | L6: 'X' | M6: '1' | N6: 'X' | O6: '1' | P6: '2' | Q6: 'X'
A7: 6 | B7: '1' | C7: '2' | D7: '2' | E7: '1' | F7: '1' | G7: 'X' | H7: '1' | I7: '1' | J7: '2' | K7: 'X' | L7: 'X' | M7: '1' | N7: '1' | O7: '1' | P7: '1' | Q7: '1'
A8: 7 | B8: '1' | C8: 'X' | D8: '1' | E8: 'X' | F8: '2' | G8: '1' | H8: '1' | I8: '1' | J8: 'X' | K8: '2' | L8: '1' | M8: '2' | N8: '1' | O8: '1' | P8: '1' | Q8: 'X'
A9: 8 | B9: 'X' | C9: '1' | D9: '1' | E9: '2' | F9: '1' | G9: 'X' | H9: '2' | I9: '1' | J9: '2' | K9: '1' | L9: '1' | M9: 'X' | N9: '1' | O9: 'X' | P9: '1' | Q9: '1'
A10: 9 | B10: '1' | C10: '2' | D10: 'X' | E10: '1' | F10: 'X' | G10: '1' | H10: '1' | I10: 'X' | J10: '2' | K10: '1' | L10: '1' | M10: '2' | N10: '1' | O10: 'X' | P10: '2' | Q10: '2'
A11: 10 | B11: '2' | C11: '1' | D11: 'X' | E11: '2' | F11: '2' | G11: '2' | H11: '1' | I11: '1' | J11: '2' | K11: 'X' | L11: '2' | M11: 'X' | N11: 'X' | O11: '1' | P11: '2' | Q11: '2'
A12: 11 | B12: 'X' | C12: '1' | D12: 'X' | E12: '1' | F12: '2' | G12: '1' | H12: '2' | I12: '1' | J12: '1' | K12: '1' | L12: 'X' | M12: '1' | N12: 'X' | O12: '1' | P12: '2' | Q12: '2'
A13: 12 | B13: '2' | C13: '1' | D13: 'X' | E13: '1' | F13: '1' | G13: 'X' | H13: 'X' | I13: '1' | J13: '1' | K13: '2' | L13: 'X' | M13: '1' | N13: '1' | O13: '2' | P13: '1' | Q13: '1'
... A15: 14 | B15: '1'] | C15: '2'] | D15: '1'] | E15: '1'] | F15: '2'] | G15: '1'] | H15: 'X'] | I15: '2'] | J15: 'X'] | K15: '1'] | L15: '1'] | M15: 'X'] | N15: '1'] | O15: '1'] | P15: '1'] | Q15: '1']
B16: 1 | C16: 5
B17: 2 | C17: 6
B18: 4 | C18: 7
B19: 8 | C19: 9
B20: 11 | C20: 10
B21: 12
B22: 13

Sheet AP8
B1: 1 | C1: 2 | D1: 3 | E1: 4 | F1: 5 | G1: 6 | H1: 7 | I1: 8 | J1: 9 | K1: 10 | L1: 11 | M1: 12 | N1: 13 | O1: 14 | P1: Num1 | Q1: NumX | R1: Num2 | S1: T | T1: DC9 | U1: DC8 | V1: DC7 | W1: DC6 | X1: DC5 | Y1: DC4 | Z1: DC3 | AA1: =800/8 -> 100 | AB1: 8
B2: 'X' | C2: '1' | D2: 'X' | E2: '2' | F2: '2' | G2: 'X' | H2: '1' | I2: '1' | J2: '1' | K2: '1' | L2: '1' | M2: '1' | N2: '2' | O2: 'X' | P2: =COUNTIF(B2:O2,A$10) -> 7 | Q2: =COUNTIF(B2:O2,A$11) -> 4 | R2: =COUNTIF(B2:O2,A$12) -> 3 | S2: =SUM(P2:R2) -> 14 | T2: =SUMPRODUCT(--(B2:O2=B$9:O$9)) -> 8 | U2: =SUMPRODUCT(--(B2:O2=B$8:O$8)) -> 8 | V2: =SUMPRODUCT(--(B2:O2=B$7:O$7)) -> 8 | W2: =SUMPRODUCT(--(B2:O2=B$6:O$6)) -> 8 | X2: =SUMPRODUCT(--(B2:O2=B$5:O$5)) -> 8 | Y2: =SUMPRODUCT(--(B2:O2=B$4:O$4)) -> 8 | Z2: =SUMPRODUCT(--(B2:O2=B$3:O$3)) -> 8 | AA2: =700/8 -> 87.5 | AB2: 7
B3: '1' | C3: '1' | D3: '1' | E3: 'X' | F3: '1' | G3: '2' | H3: '1' | I3: '1' | J3: '1' | K3: '1' | L3: '2' | M3: '1' | N3: '2' | O3: 'X' | P3: =COUNTIF(B3:O3,A$10) -> 9 | Q3: =COUNTIF(B3:O3,A$11) -> 2 | R3: =COUNTIF(B3:O3,A$12) -> 3 | S3: =SUM(P3:R3) -> 14 | T3: =SUMPRODUCT(--(B3:O3=B$9:O$9)) -> 8 | U3: =SUMPRODUCT(--(B3:O3=B$8:O$8)) -> 8 | V3: =SUMPRODUCT(--(B3:O3=B$7:O$7)) -> 8 | W3: =SUMPRODUCT(--(B3:O3=B$6:O$6)) -> 8 | X3: =SUMPRODUCT(--(B3:O3=B$5:O$5)) -> 8 | Y3: =SUMPRODUCT(--(B3:O3=B$4:O$4)) -> 8 | AA3: =600/8 -> 75 | AB3: 6
B4: '1' | C4: '1' | D4: '2' | E4: '1' | F4: '2' | G4: 'X' | H4: 'X' | I4: '1' | J4: '1' | K4: '1' | L4: '2' | M4: 'X' | N4: '2' | O4: 'X' | P4: =COUNTIF(B4:O4,A$10) -> 6 | Q4: =COUNTIF(B4:O4,A$11) -> 4 | R4: =COUNTIF(B4:O4,A$12) -> 4 | S4: =SUM(P4:R4) -> 14 | T4: =SUMPRODUCT(--(B4:O4=B$9:O$9)) -> 8 | U4: =SUMPRODUCT(--(B4:O4=B$8:O$8)) -> 8 | V4: =SUMPRODUCT(--(B4:O4=B$7:O$7)) -> 8 | W4: =SUMPRODUCT(--(B4:O4=B$6:O$6)) -> 8 | X4: =SUMPRODUCT(--(B4:O4=B$5:O$5)) -> 8 | AA4: =500/8 -> 62.5 | AB4: 5
B5: '2' | C5: '1' | D5: '1' | E5: '2' | F5: '2' | G5: '1' | H5: 'X' | I5: '1' | J5: '1' | K5: '1' | L5: '2' | M5: '1' | N5: 'X' | O5: 'X' | P5: =COUNTIF(B5:O5,A$10) -> 7 | Q5: =COUNTIF(B5:O5,A$11) -> 3 | R5: =COUNTIF(B5:O5,A$12) -> 4 | S5: =SUM(P5:R5) -> 14 | T5: =SUMPRODUCT(--(B5:O5=B$9:O$9)) -> 8 | U5: =SUMPRODUCT(--(B5:O5=B$8:O$8)) -> 8 | V5: =SUMPRODUCT(--(B5:O5=B$7:O$7)) -> 8 | W5: =SUMPRODUCT(--(B5:O5=B$6:O$6)) -> 8 | AA5: =400/8 -> 50 | AB5: 4
B6: 'X' | C6: '1' | D6: '2' | E6: 'X' | F6: '2' | G6: '1' | H6: '2' | I6: '1' | J6: '1' | K6: 'X' | L6: '2' | M6: '1' | N6: '2' | O6: 'X' | P6: =COUNTIF(B6:O6,A$10) -> 5 | Q6: =COUNTIF(B6:O6,A$11) -> 4 | R6: =COUNTIF(B6:O6,A$12) -> 5 | S6: =SUM(P6:R6) -> 14 | T6: =SUMPRODUCT(--(B6:O6=B$9:O$9)) -> 8 | U6: =SUMPRODUCT(--(B6:O6=B$8:O$8)) -> 8 | V6: =SUMPRODUCT(--(B6:O6=B$7:O$7)) -> 8 | AA6: =300/8 -> 37.5 | AB6: 3
B7: '1' | C7: '1' | D7: '2' | E7: '2' | F7: '1' | G7: '1' | H7: 'X' | I7: '1' | J7: '1' | K7: '2' | L7: '1' | M7: '1' | N7: '2' | O7: 'X' | P7: =COUNTIF(B7:O7,A$10) -> 8 | Q7: =COUNTIF(B7:O7,A$11) -> 2 | R7: =COUNTIF(B7:O7,A$12) -> 4 | S7: =SUM(P7:R7) -> 14 | T7: =SUMPRODUCT(--(B7:O7=B$9:O$9)) -> 8 | U7: =SUMPRODUCT(--(B7:O7=B$8:O$8)) -> 8 | AA7: =200/8 -> 25 | AB7: 2
B8: '1' | C8: '1' | D8: '1' | E8: '2' | F8: '2' | G8: 'X' | H8: '2' | I8: 'X' | J8: '1' | K8: '2' | L8: '2' | M8: '1' | N8: '2' | O8: 'X' | P8: =COUNTIF(B8:O8,A$10) -> 5 | Q8: =COUNTIF(B8:O8,A$11) -> 3 | R8: =COUNTIF(B8:O8,A$12) -> 6 | S8: =SUM(P8:R8) -> 14 | T8: =SUMPRODUCT(--(B8:O8=B$9:O$9)) -> 8 | AA8: =100/8 -> 12.5 | AB8: 1
B9: '1' | C9: '1' | D9: 'X' | E9: '1' | F9: '2' | G9: '1' | H9: '1' | I9: '1' | J9: '1' | K9: '2' | L9: '2' | M9: '1' | N9: '1' | O9: 'X' | P9: =COUNTIF(B9:O9,A$10) -> 9 | Q9: =COUNTIF(B9:O9,A$11) -> 2 | R9: =COUNTIF(B9:O9,A$12) -> 3 | S9: =SUM(P9:R9) -> 14
A10: '1' | B10: =COUNTIF(B2:B9,$A10) -> 5 | C10: =COUNTIF(C2:C9,$A10) -> 8 | D10: =COUNTIF(D2:D9,$A10) -> 3 | E10: =COUNTIF(E2:E9,$A10) -> 2 | F10: =COUNTIF(F2:F9,$A10) -> 2 | G10: =COUNTIF(G2:G9,$A10) -> 4 | H10: =COUNTIF(H2:H9,$A10) -> 3 | I10: =COUNTIF(I2:I9,$A10) -> 7 | ... O10: =COUNTIF(O2:O9,$A10) -> 0
A11: 'X' | B11: =COUNTIF(B2:B9,$A11) -> 2 | C11: =COUNTIF(C2:C9,$A11) -> 0 | D11: =COUNTIF(D2:D9,$A11) -> 2 | E11: =COUNTIF(E2:E9,$A11) -> 2 | F11: =COUNTIF(F2:F9,$A11) -> 0 | G11: =COUNTIF(G2:G9,$A11) -> 3 | H11: =COUNTIF(H2:H9,$A11) -> 3 | I11: =COUNTIF(I2:I9,$A11) -> 1 | ... O11: =COUNTIF(O2:O9,$A11) -> 8
A12: '2' | B12: =COUNTIF(B2:B9,$A12) -> 1 | C12: =COUNTIF(C2:C9,$A12) -> 0 | D12: =COUNTIF(D2:D9,$A12) -> 3 | E12: =COUNTIF(E2:E9,$A12) -> 4 | F12: =COUNTIF(F2:F9,$A12) -> 6 | G12: =COUNTIF(G2:G9,$A12) -> 1 | H12: =COUNTIF(H2:H9,$A12) -> 2 | I12: =COUNTIF(I2:I9,$A12) -> 0 | ... O12: =COUNTIF(O2:O9,$A12) -> 0
B13: =SUM(B10:B12) -> 8 | C13: =SUM(C10:C12) -> 8 | D13: =SUM(D10:D12) -> 8 | E13: =SUM(E10:E12) -> 8 | F13: =SUM(F10:F12) -> 8 | G13: =SUM(G10:G12) -> 8 | H13: =SUM(H10:H12) -> 8 | I13: =SUM(I10:I12) -> 8 | ... O13: =SUM(O10:O12) -> 8
A14: N1 | B14: 5 | C14: 6 | D14: 3 | E14: 4 | F14: 2 | G14: 6 | H14: 2 | I14: 4 | J14: 4 | K14: 5 | L14: 3 | M14: 6 | N14: 1 | O14: 4
A15: NX | B15: 2 | C15: 1 | D15: 3 | E15: 2 | F15: 2 | G15: 1 | H15: 2 | I15: 2 | J15: 2 | K15: 2 | L15: 3 | M15: 1 | N15: 2 | O15: 2
A16: N2 | B16: 1 | C16: 1 | D16: 2 | E16: 2 | F16: 4 | G16: 1 | H16: 4 | I16: 2 | J16: 2 | K16: 1 | L16: 2 | M16: 1 | N16: 5 | O16: 2
B17: =B10-B14 -> 0 | C17: =C10-C14 -> 2 | D17: =D10-D14 -> 0 | E17: =E10-E14 -> -2 | F17: =F10-F14 -> 0 | G17: =G10-G14 -> -2 | H17: =H10-H14 -> 1 | I17: =I10-I14 -> 3 | ... O17: =O10-O14 -> -4
B18: =B11-B15 -> 0 | C18: =C11-C15 -> -1 | D18: =D11-D15 -> -1 | E18: =E11-E15 -> 0 | F18: =F11-F15 -> -2 | G18: =G11-G15 -> 2 | H18: =H11-H15 -> 1 | I18: =I11-I15 -> -1 | ... O18: =O11-O15 -> 6
B19: =B12-B16 -> 0 | C19: =C12-C16 -> -1 | D19: =D12-D16 -> 1 | E19: =E12-E16 -> 2 | F19: =F12-F16 -> 2 | G19: =G12-G16 -> 0 | H19: =H12-H16 -> -2 | I19: =I12-I16 -> -2 | ... O19: =O12-O16 -> -2

Sheet AP16
B1: 1 | C1: 2 | D1: 3 | E1: 4 | F1: 5 | G1: 6 | H1: 7 | I1: 8 | J1: 9 | K1: 10 | L1: 11 | M1: 12 | N1: 13 | O1: 14 | P1: Num1 | Q1: NumX | R1: Num2 | T1: ICBase | U1: IC16 | V1: IC15 | W1: IC14 | X1: IC13 | Y1: IC12 | Z1: IC11 | AA1: IC10 | AB1: IC9 | AC1: IC8 | AD1: IC7 | AE1: IC6 | AF1: IC5 | AG1: IC4 | AH1: IC3 | AI1: IC2 | AJ1: =1600/16 -> 100 | AK1: 16 | AM1: 1 | AN1: =COUNTIFS(U$2:AI$16,AM1) -> 3
A2: 1 | B2: ['2' | C2: '2' | D2: '2' | E2: 'X' | F2: 'X' | G2: '2' | H2: '1' | I2: '2' | J2: '2' | K2: 'X' | L2: '1' | M2: '2' | N2: '2' | O2: 'X'] | P2: =COUNTIF(B2:O2,A$19)+COUNTIF(B2:O2,A$29)+COUNTIF(B2:O2,A$32) -> 2 | Q2: =COUNTIF(B2:O2,A$20)+COUNTIF(B2:O2,A$30)+COUNTIF(B2:O2,A$33) -> 4 | R2: =COUNTIF(B2:O2,A$21)+COUNTIF(B2:O2,A$31)+COUNTIF(B2:O2,A$34) -> 8 | S2: =SUM(P2:R2) -> 14 | T2: =SUMPRODUCT(--(B2:O2=B$18:O$18)) -> 8 | U2: =SUMPRODUCT(--(B2:O2=B$17:O$17)) -> 5 | V2: =SUMPRODUCT(--(B2:O2=B$16:O$16)) -> 5 | W2: =SUMPRODUCT(--(B2:O2=B$15:O$15)) -> 6 | X2: =SUMPRODUCT(--(B2:O2=B$14:O$14)) -> 3 | Y2: =SUMPRODUCT(--(B2:O2=B$13:O$13)) -> 5 | Z2: =SUMPRODUCT(--(B2:O2=B$12:O$12)) -> 5 | AA2: =SUMPRODUCT(--(B2:O2=B$11:O$11)) -> 6 | AB2: =SUMPRODUCT(--(B2:O2=B$10:O$10)) -> 3 | AC2: =SUMPRODUCT(--(B2:O2=B$9:O$9)) -> 6 | AD2: =SUMPRODUCT(--(B2:O2=B$8:O$8)) -> 6 | AE2: =SUMPRODUCT(--(B2:O2=B$7:O$7)) -> 5 | AF2: =SUMPRODUCT(--(B2:O2=B$6:O$6)) -> 7 | AG2: =SUMPRODUCT(--(B2:O2=B$5:O$5)) -> 6 | AH2: =SUMPRODUCT(--(B2:O2=B$4:O$4)) -> 4 | AI2: =SUMPRODUCT(--(B2:O2=B$3:O$3)) -> 2 | AJ2: =1500/16 -> 93.75 | AK2: 15 | AM2: 2 | AN2: =COUNTIFS(U$2:AI$16,AM2) -> 3
A3: 2 | B3: ['1' | C3: '2' | D3: 'X' | E3: 'X' | F3: '2' | G3: '1' | H3: 'X' | I3: '1' | J3: 'X' | K3: '2' | L3: '2' | M3: 'X' | N3: 'X' | O3: '2'] | P3: =COUNTIF(B3:O3,A$19)+COUNTIF(B3:O3,A$29)+COUNTIF(B3:O3,A$32) -> 3 | Q3: =COUNTIF(B3:O3,A$20)+COUNTIF(B3:O3,A$30)+COUNTIF(B3:O3,A$33) -> 6 | R3: =COUNTIF(B3:O3,A$21)+COUNTIF(B3:O3,A$31)+COUNTIF(B3:O3,A$34) -> 5 | S3: =SUM(P3:R3) -> 14 | T3: =SUMPRODUCT(--(B3:O3=B$18:O$18)) -> 8 | U3: =SUMPRODUCT(--(B3:O3=B$17:O$17)) -> 8 | V3: =SUMPRODUCT(--(B3:O3=B$16:O$16)) -> 7 | W3: =SUMPRODUCT(--(B3:O3=B$15:O$15)) -> 6 | X3: =SUMPRODUCT(--(B3:O3=B$14:O$14)) -> 9 | Y3: =SUMPRODUCT(--(B3:O3=B$13:O$13)) -> 4 | Z3: =SUMPRODUCT(--(B3:O3=B$12:O$12)) -> 5 | AA3: =SUMPRODUCT(--(B3:O3=B$11:O$11)) -> 5 | AB3: =SUMPRODUCT(--(B3:O3=B$10:O$10)) -> 9 | AC3: =SUMPRODUCT(--(B3:O3=B$9:O$9)) -> 4 | AD3: =SUMPRODUCT(--(B3:O3=B$8:O$8)) -> 5 | AE3: =SUMPRODUCT(--(B3:O3=B$7:O$7)) -> 6 | AF3: =SUMPRODUCT(--(B3:O3=B$6:O$6)) -> 3 | AG3: =SUMPRODUCT(--(B3:O3=B$5:O$5)) -> 7 | AH3: =SUMPRODUCT(--(B3:O3=B$4:O$4)) -> 4 | AJ3: =1400/16 -> 87.5 | AK3: 14 | AM3: 3 | AN3: =COUNTIFS(U$2:AI$16,AM3) -> 12
A4: 3 | B4: ['X' | C4: 'X' | D4: '2' | E4: '1' | F4: '1' | G4: '1' | H4: '2' | I4: '1' | J4: '2' | K4: '2' | L4: 'X' | M4: '2' | N4: '2' | O4: '2'] | P4: =COUNTIF(B4:O4,A$19)+COUNTIF(B4:O4,A$29)+COUNTIF(B4:O4,A$32) -> 4 | Q4: =COUNTIF(B4:O4,A$20)+COUNTIF(B4:O4,A$30)+COUNTIF(B4:O4,A$33) -> 3 | R4: =COUNTIF(B4:O4,A$21)+COUNTIF(B4:O4,A$31)+COUNTIF(B4:O4,A$34) -> 7 | S4: =SUM(P4:R4) -> 14 | T4: =SUMPRODUCT(--(B4:O4=B$18:O$18)) -> 8 | U4: =SUMPRODUCT(--(B4:O4=B$17:O$17)) -> 6 | V4: =SUMPRODUCT(--(B4:O4=B$16:O$16)) -> 6 | W4: =SUMPRODUCT(--(B4:O4=B$15:O$15)) -> 9 | X4: =SUMPRODUCT(--(B4:O4=B$14:O$14)) -> 6 | Y4: =SUMPRODUCT(--(B4:O4=B$13:O$13)) -> 5 | Z4: =SUMPRODUCT(--(B4:O4=B$12:O$12)) -> 6 | AA4: =SUMPRODUCT(--(B4:O4=B$11:O$11)) -> 6 | AB4: =SUMPRODUCT(--(B4:O4=B$10:O$10)) -> 7 | AC4: =SUMPRODUCT(--(B4:O4=B$9:O$9)) -> 6 | AD4: =SUMPRODUCT(--(B4:O4=B$8:O$8)) -> 4 | AE4: =SUMPRODUCT(--(B4:O4=B$7:O$7)) -> 7 | AF4: =SUMPRODUCT(--(B4:O4=B$6:O$6)) -> 6 | AG4: =SUMPRODUCT(--(B4:O4=B$5:O$5)) -> 1 | AJ4: =1300/16 -> 81.25 | AK4: 13 | AM4: 4 | AN4: =COUNTIFS(U$2:AI$16,AM4) -> 19
A5: 4 | B5: ['1' | C5: '2' | D5: '1' | E5: 'X' | F5: '2' | G5: '1' | H5: '1' | I5: 'X' | J5: '1' | K5: 'X' | L5: '1' | M5: 'X' | N5: 'X' | O5: 'X'] | P5: =COUNTIF(B5:O5,A$19)+COUNTIF(B5:O5,A$29)+COUNTIF(B5:O5,A$32) -> 6 | Q5: =COUNTIF(B5:O5,A$20)+COUNTIF(B5:O5,A$30)+COUNTIF(B5:O5,A$33) -> 6 | R5: =COUNTIF(B5:O5,A$21)+COUNTIF(B5:O5,A$31)+COUNTIF(B5:O5,A$34) -> 2 | S5: =SUM(P5:R5) -> 14 | T5: =SUMPRODUCT(--(B5:O5=B$18:O$18)) -> 7 | U5: =SUMPRODUCT(--(B5:O5=B$17:O$17)) -> 6 | V5: =SUMPRODUCT(--(B5:O5=B$16:O$16)) -> 5 | W5: =SUMPRODUCT(--(B5:O5=B$15:O$15)) -> 3 | X5: =SUMPRODUCT(--(B5:O5=B$14:O$14)) -> 6 | Y5: =SUMPRODUCT(--(B5:O5=B$13:O$13)) -> 6 | Z5: =SUMPRODUCT(--(B5:O5=B$12:O$12)) -> 5 | AA5: =SUMPRODUCT(--(B5:O5=B$11:O$11)) -> 3 | AB5: =SUMPRODUCT(--(B5:O5=B$10:O$10)) -> 3 | AC5: =SUMPRODUCT(--(B5:O5=B$9:O$9)) -> 4 | AD5: =SUMPRODUCT(--(B5:O5=B$8:O$8)) -> 7 | AE5: =SUMPRODUCT(--(B5:O5=B$7:O$7)) -> 4 | AF5: =SUMPRODUCT(--(B5:O5=B$6:O$6)) -> 5 | AJ5: =1200/16 -> 75 | AK5: 12 | AM5: 5 | AN5: =COUNTIFS(U$2:AI$16,AM5) -> 27
A6: 5 | B6: ['1' | C6: 'X' | D6: '2' | E6: '1' | F6: '2' | G6: 'X' | H6: '1' | I6: '2' | J6: '2' | K6: '2' | L6: '1' | M6: '1' | N6: '2' | O6: 'X'] | P6: =COUNTIF(B6:O6,A$19)+COUNTIF(B6:O6,A$29)+COUNTIF(B6:O6,A$32) -> 5 | Q6: =COUNTIF(B6:O6,A$20)+COUNTIF(B6:O6,A$30)+COUNTIF(B6:O6,A$33) -> 3 | R6: =COUNTIF(B6:O6,A$21)+COUNTIF(B6:O6,A$31)+COUNTIF(B6:O6,A$34) -> 6 | S6: =SUM(P6:R6) -> 14 | T6: =SUMPRODUCT(--(B6:O6=B$18:O$18)) -> 8 | U6: =SUMPRODUCT(--(B6:O6=B$17:O$17)) -> 6 | V6: =SUMPRODUCT(--(B6:O6=B$16:O$16)) -> 6 | W6: =SUMPRODUCT(--(B6:O6=B$15:O$15)) -> 4 | X6: =SUMPRODUCT(--(B6:O6=B$14:O$14)) -> 4 | Y6: =SUMPRODUCT(--(B6:O6=B$13:O$13)) -> 6 | Z6: =SUMPRODUCT(--(B6:O6=B$12:O$12)) -> 8 | AA6: =SUMPRODUCT(--(B6:O6=B$11:O$11)) -> 3 | AB6: =SUMPRODUCT(--(B6:O6=B$10:O$10)) -> 3 | AC6: =SUMPRODUCT(--(B6:O6=B$9:O$9)) -> 4 | AD6: =SUMPRODUCT(--(B6:O6=B$8:O$8)) -> 5 | AE6: =SUMPRODUCT(--(B6:O6=B$7:O$7)) -> 4 | AJ6: =1100/16 -> 68.75 | AK6: 11 | AM6: 6 | AN6: =COUNTIFS(U$2:AI$16,AM6) -> 28
A7: 6 | B7: ['2' | C7: '1' | D7: '2' | E7: '1' | F7: 'X' | G7: '1' | H7: 'X' | I7: '1' | J7: '1' | K7: '2' | L7: '1' | M7: '2' | N7: 'X' | O7: '2'] | P7: =COUNTIF(B7:O7,A$19)+COUNTIF(B7:O7,A$29)+COUNTIF(B7:O7,A$32) -> 6 | Q7: =COUNTIF(B7:O7,A$20)+COUNTIF(B7:O7,A$30)+COUNTIF(B7:O7,A$33) -> 3 | R7: =COUNTIF(B7:O7,A$21)+COUNTIF(B7:O7,A$31)+COUNTIF(B7:O7,A$34) -> 5 | S7: =SUM(P7:R7) -> 14 | T7: =SUMPRODUCT(--(B7:O7=B$18:O$18)) -> 7 | U7: =SUMPRODUCT(--(B7:O7=B$17:O$17)) -> 7 | V7: =SUMPRODUCT(--(B7:O7=B$16:O$16)) -> 4 | W7: =SUMPRODUCT(--(B7:O7=B$15:O$15)) -> 7 | X7: =SUMPRODUCT(--(B7:O7=B$14:O$14)) -> 5 | Y7: =SUMPRODUCT(--(B7:O7=B$13:O$13)) -> 3 | Z7: =SUMPRODUCT(--(B7:O7=B$12:O$12)) -> 5 | AA7: =SUMPRODUCT(--(B7:O7=B$11:O$11)) -> 5 | AB7: =SUMPRODUCT(--(B7:O7=B$10:O$10)) -> 6 | AC7: =SUMPRODUCT(--(B7:O7=B$9:O$9)) -> 5 | AD7: =SUMPRODUCT(--(B7:O7=B$8:O$8)) -> 1 | AJ7: =1000/16 -> 62.5 | AK7: 10 | AM7: 7 | AN7: =COUNTIFS(U$2:AI$16,AM7) -> 14
A8: 7 | B8: ['1' | C8: '2' | D8: '1' | E8: '2' | F8: '2' | G8: '2' | H8: '1' | I8: '1' | J8: '2' | K8: 'X' | L8: 'X' | M8: 'X' | N8: '2' | O8: '1'] | P8: =COUNTIF(B8:O8,A$19)+COUNTIF(B8:O8,A$29)+COUNTIF(B8:O8,A$32) -> 5 | Q8: =COUNTIF(B8:O8,A$20)+COUNTIF(B8:O8,A$30)+COUNTIF(B8:O8,A$33) -> 3 | R8: =COUNTIF(B8:O8,A$21)+COUNTIF(B8:O8,A$31)+COUNTIF(B8:O8,A$34) -> 6 | S8: =SUM(P8:R8) -> 14 | T8: =SUMPRODUCT(--(B8:O8=B$18:O$18)) -> 7 | U8: =SUMPRODUCT(--(B8:O8=B$17:O$17)) -> 5 | V8: =SUMPRODUCT(--(B8:O8=B$16:O$16)) -> 3 | W8: =SUMPRODUCT(--(B8:O8=B$15:O$15)) -> 7 | X8: =SUMPRODUCT(--(B8:O8=B$14:O$14)) -> 5 | Y8: =SUMPRODUCT(--(B8:O8=B$13:O$13)) -> 4 | Z8: =SUMPRODUCT(--(B8:O8=B$12:O$12)) -> 6 | AA8: =SUMPRODUCT(--(B8:O8=B$11:O$11)) -> 4 | AB8: =SUMPRODUCT(--(B8:O8=B$10:O$10)) -> 5 | AC8: =SUMPRODUCT(--(B8:O8=B$9:O$9)) -> 3 | AJ8: =900/16 -> 56.25 | AK8: 9 | AM8: 8 | AN8: =COUNTIFS(U$2:AI$16,AM8) -> 8
A9: 8 | B9: ['1' | C9: '1' | D9: '2' | E9: 'X' | F9: '1' | G9: '2' | H9: '2' | I9: 'X' | J9: 'X' | K9: '1' | L9: '1' | M9: '2' | N9: '2' | O9: '2'] | P9: =COUNTIF(B9:O9,A$19)+COUNTIF(B9:O9,A$29)+COUNTIF(B9:O9,A$32) -> 5 | Q9: =COUNTIF(B9:O9,A$20)+COUNTIF(B9:O9,A$30)+COUNTIF(B9:O9,A$33) -> 3 | R9: =COUNTIF(B9:O9,A$21)+COUNTIF(B9:O9,A$31)+COUNTIF(B9:O9,A$34) -> 6 | S9: =SUM(P9:R9) -> 14 | T9: =SUMPRODUCT(--(B9:O9=B$18:O$18)) -> 7 | U9: =SUMPRODUCT(--(B9:O9=B$17:O$17)) -> 4 | V9: =SUMPRODUCT(--(B9:O9=B$16:O$16)) -> 4 | W9: =SUMPRODUCT(--(B9:O9=B$15:O$15)) -> 4 | X9: =SUMPRODUCT(--(B9:O9=B$14:O$14)) -> 5 | Y9: =SUMPRODUCT(--(B9:O9=B$13:O$13)) -> 5 | Z9: =SUMPRODUCT(--(B9:O9=B$12:O$12)) -> 4 | AA9: =SUMPRODUCT(--(B9:O9=B$11:O$11)) -> 6 | AB9: =SUMPRODUCT(--(B9:O9=B$10:O$10)) -> 2 | AJ9: =800/16 -> 50 | AK9: 8 | AM9: 9 | AN9: =COUNTIFS(U$2:AI$16,AM9) -> 5
A10: 9 | B10: ['X' | C10: '2' | D10: 'X' | E10: '2' | F10: '2' | G10: '1' | H10: 'X' | I10: '1' | J10: '2' | K10: '2' | L10: '2' | M10: '2' | N10: '1' | O10: '2'] | P10: =COUNTIF(B10:O10,A$19)+COUNTIF(B10:O10,A$29)+COUNTIF(B10:O10,A$32) -> 3 | Q10: =COUNTIF(B10:O10,A$20)+COUNTIF(B10:O10,A$30)+COUNTIF(B10:O10,A$33) -> 3 | R10: =COUNTIF(B10:O10,A$21)+COUNTIF(B10:O10,A$31)+COUNTIF(B10:O10,A$34) -> 8 | S10: =SUM(P10:R10) -> 14 | T10: =SUMPRODUCT(--(B10:O10=B$18:O$18)) -> 8 | U10: =SUMPRODUCT(--(B10:O10=B$17:O$17)) -> 8 | V10: =SUMPRODUCT(--(B10:O10=B$16:O$16)) -> 9 | W10: =SUMPRODUCT(--(B10:O10=B$15:O$15)) -> 7 | X10: =SUMPRODUCT(--(B10:O10=B$14:O$14)) -> 10 | Y10: =SUMPRODUCT(--(B10:O10=B$13:O$13)) -> 6 | Z10: =SUMPRODUCT(--(B10:O10=B$12:O$12)) -> 5 | AA10: =SUMPRODUCT(--(B10:O10=B$11:O$11)) -> 6 | AJ10: =700/16 -> 43.75 | AK10: 7 | AM10: 10 | AN10: =COUNTIFS(U$2:AI$16,AM10) -> 1
A11: 10 | B11: ['X' | C11: '2' | D11: '2' | E11: 'X' | F11: 'X' | G11: 'X' | H11: '1' | I11: '1' | J11: 'X' | K11: '1' | L11: 'X' | M11: '2' | N11: '1' | O11: '2'] | P11: =COUNTIF(B11:O11,A$19)+COUNTIF(B11:O11,A$29)+COUNTIF(B11:O11,A$32) -> 4 | Q11: =COUNTIF(B11:O11,A$20)+COUNTIF(B11:O11,A$30)+COUNTIF(B11:O11,A$33) -> 6 | R11: =COUNTIF(B11:O11,A$21)+COUNTIF(B11:O11,A$31)+COUNTIF(B11:O11,A$34) -> 4 | S11: =SUM(P11:R11) -> 14 | T11: =SUMPRODUCT(--(B11:O11=B$18:O$18)) -> 7 | U11: =SUMPRODUCT(--(B11:O11=B$17:O$17)) -> 2 | V11: =SUMPRODUCT(--(B11:O11=B$16:O$16)) -> 5 | W11: =SUMPRODUCT(--(B11:O11=B$15:O$15)) -> 6 | X11: =SUMPRODUCT(--(B11:O11=B$14:O$14)) -> 3 | Y11: =SUMPRODUCT(--(B11:O11=B$13:O$13)) -> 7 | Z11: =SUMPRODUCT(--(B11:O11=B$12:O$12)) -> 1 | AJ11: =600/16 -> 37.5 | AK11: 6 | AM11: 11 | AN11: =COUNTIFS(U$2:AI$16,AM11) -> 0
A12: 11 | B12: ['1' | C12: '2' | D12: '1' | E12: '1' | F12: '1' | G12: '1' | H12: 'X' | I12: '2' | J12: '2' | K12: '2' | L12: '1' | M12: '1' | N12: '2' | O12: '1'] | P12: =COUNTIF(B12:O12,A$19)+COUNTIF(B12:O12,A$29)+COUNTIF(B12:O12,A$32) -> 8 | Q12: =COUNTIF(B12:O12,A$20)+COUNTIF(B12:O12,A$30)+COUNTIF(B12:O12,A$33) -> 1 | R12: =COUNTIF(B12:O12,A$21)+COUNTIF(B12:O12,A$31)+COUNTIF(B12:O12,A$34) -> 5 | S12: =SUM(P12:R12) -> 14 | T12: =SUMPRODUCT(--(B12:O12=B$18:O$18)) -> 7 | U12: =SUMPRODUCT(--(B12:O12=B$17:O$17)) -> 8 | V12: =SUMPRODUCT(--(B12:O12=B$16:O$16)) -> 7 | W12: =SUMPRODUCT(--(B12:O12=B$15:O$15)) -> 5 | X12: =SUMPRODUCT(--(B12:O12=B$14:O$14)) -> 5 | Y12: =SUMPRODUCT(--(B12:O12=B$13:O$13)) -> 7 | AJ12: =500/16 -> 31.25 | AK12: 5 | AM12: 12 | AN12: =COUNTIFS(U$2:AI$16,AM12) -> 0
A13: 12 | B13: ['X' | C13: '2' | D13: '1' | E13: 'X' | F13: '1' | G13: 'X' | H13: '1' | I13: 'X' | J13: '2' | K13: '2' | L13: '1' | M13: '1' | N13: '1' | O13: '2'] | P13: =COUNTIF(B13:O13,A$19)+COUNTIF(B13:O13,A$29)+COUNTIF(B13:O13,A$32) -> 6 | Q13: =COUNTIF(B13:O13,A$20)+COUNTIF(B13:O13,A$30)+COUNTIF(B13:O13,A$33) -> 4 | R13: =COUNTIF(B13:O13,A$21)+COUNTIF(B13:O13,A$31)+COUNTIF(B13:O13,A$34) -> 4 | S13: =SUM(P13:R13) -> 14 | T13: =SUMPRODUCT(--(B13:O13=B$18:O$18)) -> 7 | U13: =SUMPRODUCT(--(B13:O13=B$17:O$17)) -> 6 | V13: =SUMPRODUCT(--(B13:O13=B$16:O$16)) -> 9 | W13: =SUMPRODUCT(--(B13:O13=B$15:O$15)) -> 4 | X13: =SUMPRODUCT(--(B13:O13=B$14:O$14)) -> 5 | AJ13: =400/16 -> 25 | AK13: 4 | AM13: 13 | AN13: =COUNTIFS(U$2:AI$16,AM13) -> 0
A14: 13 | B14: ['1' | C14: '2' | D14: 'X' | E14: '2' | F14: '2' | G14: '1' | H14: '2' | I14: 'X' | J14: '2' | K14: '2' | L14: '2' | M14: '2' | N14: 'X' | O14: '2'] | P14: =COUNTIF(B14:O14,A$19)+COUNTIF(B14:O14,A$29)+COUNTIF(B14:O14,A$32) -> 2 | Q14: =COUNTIF(B14:O14,A$20)+COUNTIF(B14:O14,A$30)+COUNTIF(B14:O14,A$33) -> 3 | R14: =COUNTIF(B14:O14,A$21)+COUNTIF(B14:O14,A$31)+COUNTIF(B14:O14,A$34) -> 9 | S14: =SUM(P14:R14) -> 14 | T14: =SUMPRODUCT(--(B14:O14=B$18:O$18)) -> 8 | U14: =SUMPRODUCT(--(B14:O14=B$17:O$17)) -> 8 | V14: =SUMPRODUCT(--(B14:O14=B$16:O$16)) -> 8 | W14: =SUMPRODUCT(--(B14:O14=B$15:O$15)) -> 7 | AJ14: =300/16 -> 18.75 | AK14: 3 | AM14: 14 | AN14: =COUNTIFS(U$2:AI$16,AM14) -> 0
A15: 14 | B15: ['2' | C15: '2' | D15: '2' | E15: '2' | F15: 'X' | G15: '1' | H15: '2' | I15: '1' | J15: '2' | K15: '2' | L15: 'X' | M15: 'X' | N15: '2' | O15: '2'] | P15: =COUNTIF(B15:O15,A$19)+COUNTIF(B15:O15,A$29)+COUNTIF(B15:O15,A$32) -> 2 | Q15: =COUNTIF(B15:O15,A$20)+COUNTIF(B15:O15,A$30)+COUNTIF(B15:O15,A$33) -> 3 | R15: =COUNTIF(B15:O15,A$21)+COUNTIF(B15:O15,A$31)+COUNTIF(B15:O15,A$34) -> 9 | S15: =SUM(P15:R15) -> 14 | T15: =SUMPRODUCT(--(B15:O15=B$18:O$18)) -> 8 | U15: =SUMPRODUCT(--(B15:O15=B$17:O$17)) -> 8 | V15: =SUMPRODUCT(--(B15:O15=B$16:O$16)) -> 6 | AJ15: =200/16 -> 12.5 | AK15: 2
A16: 15 | B16: ['X' | C16: '2' | D16: 'X' | E16: 'X' | F16: '2' | G16: '1' | H16: '2' | I16: '2' | J16: '2' | K16: '2' | L16: '1' | M16: '1' | N16: '1' | O16: '2'] | P16: =COUNTIF(B16:O16,A$19)+COUNTIF(B16:O16,A$29)+COUNTIF(B16:O16,A$32) -> 4 | Q16: =COUNTIF(B16:O16,A$20)+COUNTIF(B16:O16,A$30)+COUNTIF(B16:O16,A$33) -> 3 | R16: =COUNTIF(B16:O16,A$21)+COUNTIF(B16:O16,A$31)+COUNTIF(B16:O16,A$34) -> 7 | S16: =SUM(P16:R16) -> 14 | T16: =SUMPRODUCT(--(B16:O16=B$18:O$18)) -> 8 | U16: =SUMPRODUCT(--(B16:O16=B$17:O$17)) -> 8 | AJ16: =100/16 -> 6.25 | AK16: 1
A17: 16 | B17: ['2' | C17: '2' | D17: 'X' | E17: '1' | F17: '2' | G17: '1' | H17: 'X' | I17: 'X' | J17: '2' | K17: '2' | L17: '1' | M17: 'X' | N17: '2' | O17: '2'] | P17: =COUNTIF(B17:O17,A$19)+COUNTIF(B17:O17,A$29)+COUNTIF(B17:O17,A$32) -> 3 | Q17: =COUNTIF(B17:O17,A$20)+COUNTIF(B17:O17,A$30)+COUNTIF(B17:O17,A$33) -> 4 | R17: =COUNTIF(B17:O17,A$21)+COUNTIF(B17:O17,A$31)+COUNTIF(B17:O17,A$34) -> 7 | S17: =SUM(P17:R17) -> 14 | T17: =SUMPRODUCT(--(B17:O17=B$18:O$18)) -> 8
A18: B | B18: ['1' | C18: '2' | D18: '2' | E18: 'X' | F18: '2' | G18: '1' | H18: '1' | I18: '1' | J18: '2' | K18: '2' | L18: '1' | M18: '2' | N18: '2' | O18: '2']
A19: '1' | B19: =COUNTIF(B2:B17,$A29) -> 7 | C19: =COUNTIF(C2:C17,$A19) -> 2 | D19: =COUNTIF(D2:D17,$A19) -> 4 | E19: =COUNTIF(E2:E17,$A19) -> 5 | F19: =COUNTIF(F2:F17,$A19) -> 4 | G19: =COUNTIF(G2:G17,$A19) -> 10 | H19: =COUNTIF(H2:H17,$A19) -> 6 | I19: =COUNTIF(I2:I17,$A19) -> 7 | J19: =COUNTIF(J2:J17,$A19) -> 2 | ... N19: =COUNTIF(N2:N17,$A19) -> 4 | O19: =COUNTIF(O2:O17,$A32) -> 2 | U19: =SUM(U2:U16) -> 95 | V19: =SUM(V2:V16) -> 84 | W19: =SUM(W2:W16) -> 75 | X19: =SUM(X2:X16) -> 66 | Y19: =SUM(Y2:Y16) -> 58 | Z19: =SUM(Z2:Z16) -> 50 | AA19: =SUM(AA2:AA16) -> 44 | AB19: =SUM(AB2:AB16) -> 38 | ... AI19: =SUM(AI2:AI16) -> 2 | AJ19: =SUM(U19:AI19) -> 641
A20: 'X' | B20: =COUNTIF(B2:B17,$A30) -> 5 | C20: =COUNTIF(C2:C17,$A20) -> 2 | D20: =COUNTIF(D2:D17,$A20) -> 5 | E20: =COUNTIF(E2:E17,$A20) -> 7 | F20: =COUNTIF(F2:F17,$A20) -> 4 | G20: =COUNTIF(G2:G17,$A20) -> 3 | H20: =COUNTIF(H2:H17,$A20) -> 5 | I20: =COUNTIF(I2:I17,$A20) -> 5 | J20: =COUNTIF(J2:J17,$A20) -> 3 | ... N20: =COUNTIF(N2:N17,$A20) -> 4 | O20: =COUNTIF(O2:O17,$A33) -> 3
A21: '2' | B21: =COUNTIF(B2:B17,$A31) -> 4 | C21: =COUNTIF(C2:C17,$A21) -> 12 | D21: =COUNTIF(D2:D17,$A21) -> 7 | E21: =COUNTIF(E2:E17,$A21) -> 4 | F21: =COUNTIF(F2:F17,$A21) -> 8 | G21: =COUNTIF(G2:G17,$A21) -> 3 | H21: =COUNTIF(H2:H17,$A21) -> 5 | I21: =COUNTIF(I2:I17,$A21) -> 4 | J21: =COUNTIF(J2:J17,$A21) -> 11 | ... N21: =COUNTIF(N2:N17,$A21) -> 8 | O21: =COUNTIF(O2:O17,$A34) -> 11 | R21: pares | U21: trios
B22: =SUM(B19:B21) -> 16 | C22: =SUM(C19:C21) -> 16 | D22: =SUM(D19:D21) -> 16 | E22: =SUM(E19:E21) -> 16 | F22: =SUM(F19:F21) -> 16 | G22: =SUM(G19:G21) -> 16 | H22: =SUM(H19:H21) -> 16 | I22: =SUM(I19:I21) -> 16 | ... O22: =SUM(O19:O21) -> 16 | Q22: 0 | R22: =COUNTIFS(C$55:O$67,Q54) -> 1 | T22: 0 | U22: =AA55 -> 104
A23: N1 | B23: =Sheet1!R2 -> 16 | C23: =Sheet1!R3 -> 12 | D23: =Sheet1!R4 -> 8 | E23: =Sheet1!R5 -> 20 | F23: =Sheet1!R6 -> 16 | G23: =Sheet1!R7 -> 16 | H23: =Sheet1!R8 -> 15 | I23: =Sheet1!R9 -> 10 | J23: =Sheet1!R10 -> 18 | K23: =Sheet1!R11 -> 13 | L23: =Sheet1!R12 -> 12 | M23: =Sheet1!R13 -> 8 | N23: =Sheet1!R14 -> 12 | O23: =Sheet1!R15 -> 17 | Q23: 1 | R23: =COUNTIFS(C$55:O$67,Q55) -> 15 | T23: 1 | U23: =AA56 -> 149
A24: NX | B24: =Sheet1!S2 -> 9 | C24: =Sheet1!S3 -> 10 | D24: =Sheet1!S4 -> 10 | E24: =Sheet1!S5 -> 7 | F24: =Sheet1!S6 -> 8 | G24: =Sheet1!S7 -> 8 | H24: =Sheet1!S8 -> 10 | I24: =Sheet1!S9 -> 8 | J24: =Sheet1!S10 -> 6 | K24: =Sheet1!S11 -> 9 | L24: =Sheet1!S12 -> 11 | M24: =Sheet1!S13 -> 10 | N24: =Sheet1!S14 -> 9 | O24: =Sheet1!S15 -> 6 | Q24: 2 | R24: =COUNTIFS(C$55:O$67,Q56) -> 21 | T24: 2 | U24: =AA57 -> 69
A25: N2 | B25: =Sheet1!T2 -> 7 | C25: =Sheet1!T3 -> 10 | D25: =Sheet1!T4 -> 14 | E25: =Sheet1!T5 -> 5 | F25: =Sheet1!T6 -> 8 | G25: =Sheet1!T7 -> 8 | H25: =Sheet1!T8 -> 7 | I25: =Sheet1!T9 -> 14 | J25: =Sheet1!T10 -> 8 | K25: =Sheet1!T11 -> 10 | L25: =Sheet1!T12 -> 9 | M25: =Sheet1!T13 -> 14 | N25: =Sheet1!T14 -> 11 | O25: =Sheet1!T15 -> 9 | Q25: 3 | R25: =COUNTIFS(C$55:O$67,Q57) -> 19 | T25: 3 | U25: =AA58 -> 32
B26: =B19-B23 -> -9 | C26: =C19-C23 -> -10 | D26: =D19-D23 -> -4 | E26: =E19-E23 -> -15 | F26: =F19-F23 -> -12 | G26: =G19-G23 -> -6 | H26: =H19-H23 -> -9 | I26: =I19-I23 -> -3 | ... O26: =O19-O23 -> -15 | Q26: 4 | R26: =COUNTIFS(C$55:O$67,Q58) -> 17 | T26: 4 | U26: =AA59 -> 8
B27: =B20-B24 -> -4 | C27: =C20-C24 -> -8 | D27: =D20-D24 -> -5 | E27: =E20-E24 -> 0 | F27: =F20-F24 -> -4 | G27: =G20-G24 -> -5 | H27: =H20-H24 -> -5 | I27: =I20-I24 -> -3 | ... O27: =O20-O24 -> -3 | Q27: 5 | R27: =COUNTIFS(C$55:O$67,Q59) -> 10 | T27: 5 | U27: =AA60 -> 2
B28: =B21-B25 -> -3 | C28: =C21-C25 -> 2 | D28: =D21-D25 -> -7 | E28: =E21-E25 -> -1 | F28: =F21-F25 -> 0 | G28: =G21-G25 -> -5 | H28: =H21-H25 -> -2 | I28: =I21-I25 -> -10 | ... O28: =O21-O25 -> 2 | P28: =SUMIF(B26:O28,"<0") -> -232 | Q28: 6 | R28: =COUNTIFS(C$55:O$67,Q60) -> 6 | T28: 6 | U28: =AA61 -> 0
A29: ['1' | Q29: 7 | R29: =COUNTIFS(C$55:O$67,Q61) -> 2 | T29: 7 | U29: =AA62 -> 0
A30: ['X' | Q30: 8 | R30: =COUNTIFS(C$55:O$67,Q62) -> 0 | T30: 8 | U30: =AA63 -> 0
A31: ['2' | Q31: 9 | R31: =COUNTIFS(C$55:O$67,Q63) -> 0 | T31: 9 | U31: =AA64 -> 0
A32: '1'] | Q32: 10 | R32: =COUNTIFS(C$55:O$67,Q64) -> 0 | T32: 10 | U32: =AA65 -> 0
A33: 'X']
A34: '2']
B35: Posiciones distinta a la base
B36: 1 | C36: 2 | D36: 3 | E36: 4 | F36: 5 | G36: 6 | H36: 7 | I36: 8 | J36: 9 | K36: 10 | L36: 11 | M36: 12 | N36: 13 | O36: 14
A37: 1 | B37: =IF(B2<>B$18,"X","") -> X | C37: =IF(C2<>C$18,"X","") | D37: =IF(D2<>D$18,"X","") | E37: =IF(E2<>E$18,"X","") | F37: =IF(F2<>F$18,"X","") -> X | G37: =IF(G2<>G$18,"X","") -> X | H37: =IF(H2<>H$18,"X","") | I37: =IF(I2<>I$18,"X","") -> X | ... O37: =IF(O2<>O$18,"X","") -> X
A38: 2 | B38: =IF(B3<>B$18,"X","") | C38: =IF(C3<>C$18,"X","") | D38: =IF(D3<>D$18,"X","") -> X | E38: =IF(E3<>E$18,"X","") | F38: =IF(F3<>F$18,"X","") | G38: =IF(G3<>G$18,"X","") | H38: =IF(H3<>H$18,"X","") -> X | I38: =IF(I3<>I$18,"X","") | ... O38: =IF(O3<>O$18,"X","")
A39: 3 | B39: =IF(B4<>B$18,"X","") -> X | C39: =IF(C4<>C$18,"X","") -> X | D39: =IF(D4<>D$18,"X","") | E39: =IF(E4<>E$18,"X","") -> X | F39: =IF(F4<>F$18,"X","") -> X | G39: =IF(G4<>G$18,"X","") | H39: =IF(H4<>H$18,"X","") -> X | I39: =IF(I4<>I$18,"X","") | ... O39: =IF(O4<>O$18,"X","")
A40: 4 | B40: =IF(B5<>B$18,"X","") | C40: =IF(C5<>C$18,"X","") | D40: =IF(D5<>D$18,"X","") -> X | E40: =IF(E5<>E$18,"X","") | F40: =IF(F5<>F$18,"X","") | G40: =IF(G5<>G$18,"X","") | H40: =IF(H5<>H$18,"X","") | I40: =IF(I5<>I$18,"X","") -> X | ... O40: =IF(O5<>O$18,"X","") -> X
...

Sheet AP24
B1: 1 | C1: 2 | D1: 3 | E1: 4 | F1: 5 | G1: 6 | H1: 7 | I1: 8 | J1: 9 | K1: 10 | L1: 11 | M1: 12 | N1: 13 | O1: 14 | P1: Num1 | Q1: NumX | R1: Num2 | T1: DC25 | U1: DC24 | V1: DC23 | W1: DC22 | X1: DC21 | Y1: DC20 | Z1: DC19 | AA1: DC18 | AB1: DC17 | AC1: DC16 | AD1: DC15 | AE1: DC14 | AF1: DC13 | AG1: DC12 | AH1: DC11 | AI1: DC10 | AJ1: DC9 | AK1: DC8 | AL1: DC7 | AM1: DC6 | AN1: DC5 | AO1: DC4 | AP1: DC3 | AR1: 0 | AS1: =COUNTIFS(T$2:AP$24,AR1) -> 0
B2: ['X' | C2: 'X' | D2: '1' | E2: '1' | F2: '1' | G2: '2' | H2: '1' | I2: 'X' | J2: 'X' | K2: '1' | L2: 'X' | M2: '2' | N2: '2' | O2: '2'] | P2: =COUNTIF(B2:O2,A$26)+COUNTIF(B2:O2,A$36)+COUNTIF(B2:O2,A$39) -> 5 | Q2: =COUNTIF(B2:O2,A$27)+COUNTIF(B2:O2,A$37)+COUNTIF(B2:O2,A$40) -> 5 | R2: =COUNTIF(B2:O2,A$28)+COUNTIF(B2:O2,A$38)+COUNTIF(B2:O2,A$41) -> 4 | S2: =SUM(P2:R2) -> 14 | T2: =SUMPRODUCT(--(B2:O2=B$25:O$25)) -> 1 | U2: =SUMPRODUCT(--(B2:O2=B$24:O$24)) -> 2 | V2: =SUMPRODUCT(--(B2:O2=B$23:O$23)) -> 1 | W2: =SUMPRODUCT(--(B2:O2=B$22:O$22)) -> 5 | X2: =SUMPRODUCT(--(B2:O2=B$21:O$21)) -> 3 | Y2: =SUMPRODUCT(--(B2:O2=B$20:O$20)) -> 4 | Z2: =SUMPRODUCT(--(B2:O2=B$19:O$19)) -> 3 | AA2: =SUMPRODUCT(--(B2:O2=B$18:O$18)) -> 4 | AB2: =SUMPRODUCT(--(B2:O2=B$17:O$17)) -> 4 | AC2: =SUMPRODUCT(--(B2:O2=B$16:O$16)) -> 6 | AD2: =SUMPRODUCT(--(B2:O2=B$15:O$15)) -> 5 | AE2: =SUMPRODUCT(--(B2:O2=B$14:O$14)) -> 5 | AF2: =SUMPRODUCT(--(B2:O2=B$13:O$13)) -> 4 | AG2: =SUMPRODUCT(--(B2:O2=B$12:O$12)) -> 3 | AH2: =SUMPRODUCT(--(B2:O2=B$11:O$11)) -> 9 | AI2: =SUMPRODUCT(--(B2:O2=B$10:O$10)) -> 2 | AJ2: =SUMPRODUCT(--(B2:O2=B$9:O$9)) -> 5 | AK2: =SUMPRODUCT(--(B2:O2=B$8:O$8)) -> 5 | AL2: =SUMPRODUCT(--(B2:O2=B$7:O$7)) -> 7 | AM2: =SUMPRODUCT(--(B2:O2=B$6:O$6)) -> 4 | AN2: =SUMPRODUCT(--(B2:O2=B$5:O$5)) -> 6 | AO2: =SUMPRODUCT(--(B2:O2=B$4:O$4)) -> 7 | AP2: =SUMPRODUCT(--(B2:O2=B$3:O$3)) -> 5 | AR2: 1 | AS2: =COUNTIFS(T$2:AP$24,AR2) -> 2
B3: ['X' | C3: '1' | D3: '1' | E3: 'X' | F3: '1' | G3: '1' | H3: '1' | I3: '1' | J3: 'X' | K3: '2' | L3: '1' | M3: '1' | N3: 'X' | O3: '1'] | P3: =COUNTIF(B3:O3,A$26)+COUNTIF(B3:O3,A$36)+COUNTIF(B3:O3,A$39) -> 9 | Q3: =COUNTIF(B3:O3,A$27)+COUNTIF(B3:O3,A$37)+COUNTIF(B3:O3,A$40) -> 4 | R3: =COUNTIF(B3:O3,A$28)+COUNTIF(B3:O3,A$38)+COUNTIF(B3:O3,A$41) -> 1 | S3: =SUM(P3:R3) -> 14 | T3: =SUMPRODUCT(--(B3:O3=B$25:O$25)) -> 3 | U3: =SUMPRODUCT(--(B3:O3=B$24:O$24)) -> 6 | V3: =SUMPRODUCT(--(B3:O3=B$23:O$23)) -> 7 | W3: =SUMPRODUCT(--(B3:O3=B$22:O$22)) -> 7 | X3: =SUMPRODUCT(--(B3:O3=B$21:O$21)) -> 8 | Y3: =SUMPRODUCT(--(B3:O3=B$20:O$20)) -> 5 | Z3: =SUMPRODUCT(--(B3:O3=B$19:O$19)) -> 7 | AA3: =SUMPRODUCT(--(B3:O3=B$18:O$18)) -> 4 | AB3: =SUMPRODUCT(--(B3:O3=B$17:O$17)) -> 7 | AC3: =SUMPRODUCT(--(B3:O3=B$16:O$16)) -> 5 | AD3: =SUMPRODUCT(--(B3:O3=B$15:O$15)) -> 7 | AE3: =SUMPRODUCT(--(B3:O3=B$14:O$14)) -> 6 | AF3: =SUMPRODUCT(--(B3:O3=B$13:O$13)) -> 8 | AG3: =SUMPRODUCT(--(B3:O3=B$12:O$12)) -> 8 | AH3: =SUMPRODUCT(--(B3:O3=B$11:O$11)) -> 7 | AI3: =SUMPRODUCT(--(B3:O3=B$10:O$10)) -> 6 | AJ3: =SUMPRODUCT(--(B3:O3=B$9:O$9)) -> 8 | AK3: =SUMPRODUCT(--(B3:O3=B$8:O$8)) -> 6 | AL3: =SUMPRODUCT(--(B3:O3=B$7:O$7)) -> 3 | AM3: =SUMPRODUCT(--(B3:O3=B$6:O$6)) -> 6 | AN3: =SUMPRODUCT(--(B3:O3=B$5:O$5)) -> 6 | AO3: =SUMPRODUCT(--(B3:O3=B$4:O$4)) -> 5 | AR3: 2 | AS3: =COUNTIFS(T$2:AP$24,AR3) -> 12
B4: ['1' | C4: '1' | D4: 'X' | E4: '1' | F4: '1' | G4: 'X' | H4: '1' | I4: 'X' | J4: 'X' | K4: 'X' | L4: '1' | M4: 'X' | N4: '2' | O4: '2'] | P4: =COUNTIF(B4:O4,A$26)+COUNTIF(B4:O4,A$36)+COUNTIF(B4:O4,A$39) -> 6 | Q4: =COUNTIF(B4:O4,A$27)+COUNTIF(B4:O4,A$37)+COUNTIF(B4:O4,A$40) -> 6 | R4: =COUNTIF(B4:O4,A$28)+COUNTIF(B4:O4,A$38)+COUNTIF(B4:O4,A$41) -> 2 | S4: =SUM(P4:R4) -> 14 | T4: =SUMPRODUCT(--(B4:O4=B$25:O$25)) -> 4 | U4: =SUMPRODUCT(--(B4:O4=B$24:O$24)) -> 3 | V4: =SUMPRODUCT(--(B4:O4=B$23:O$23)) -> 4 | W4: =SUMPRODUCT(--(B4:O4=B$22:O$22)) -> 4 | X4: =SUMPRODUCT(--(B4:O4=B$21:O$21)) -> 4 | Y4: =SUMPRODUCT(--(B4:O4=B$20:O$20)) -> 4 | Z4: =SUMPRODUCT(--(B4:O4=B$19:O$19)) -> 5 | AA4: =SUMPRODUCT(--(B4:O4=B$18:O$18)) -> 4 | AB4: =SUMPRODUCT(--(B4:O4=B$17:O$17)) -> 7 | AC4: =SUMPRODUCT(--(B4:O4=B$16:O$16)) -> 8 | AD4: =SUMPRODUCT(--(B4:O4=B$15:O$15)) -> 5 | AE4: =SUMPRODUCT(--(B4:O4=B$14:O$14)) -> 5 | AF4: =SUMPRODUCT(--(B4:O4=B$13:O$13)) -> 6 | AG4: =SUMPRODUCT(--(B4:O4=B$12:O$12)) -> 4 | AH4: =SUMPRODUCT(--(B4:O4=B$11:O$11)) -> 6 | AI4: =SUMPRODUCT(--(B4:O4=B$10:O$10)) -> 4 | AJ4: =SUMPRODUCT(--(B4:O4=B$9:O$9)) -> 5 | AK4: =SUMPRODUCT(--(B4:O4=B$8:O$8)) -> 6 | AL4: =SUMPRODUCT(--(B4:O4=B$7:O$7)) -> 6 | AM4: =SUMPRODUCT(--(B4:O4=B$6:O$6)) -> 2 | AN4: =SUMPRODUCT(--(B4:O4=B$5:O$5)) -> 5 | AR4: 3 | AS4: =COUNTIFS(T$2:AP$24,AR4) -> 21
B5: ['2' | C5: 'X' | D5: '1' | E5: '1' | F5: '2' | G5: '1' | H5: '1' | I5: '2' | J5: 'X' | K5: '1' | L5: '1' | M5: 'X' | N5: '1' | O5: '1'] | P5: =COUNTIF(B5:O5,A$26)+COUNTIF(B5:O5,A$36)+COUNTIF(B5:O5,A$39) -> 8 | Q5: =COUNTIF(B5:O5,A$27)+COUNTIF(B5:O5,A$37)+COUNTIF(B5:O5,A$40) -> 3 | R5: =COUNTIF(B5:O5,A$28)+COUNTIF(B5:O5,A$38)+COUNTIF(B5:O5,A$41) -> 3 | S5: =SUM(P5:R5) -> 14 | T5: =SUMPRODUCT(--(B5:O5=B$25:O$25)) -> 4 | U5: =SUMPRODUCT(--(B5:O5=B$24:O$24)) -> 5 | V5: =SUMPRODUCT(--(B5:O5=B$23:O$23)) -> 7 | W5: =SUMPRODUCT(--(B5:O5=B$22:O$22)) -> 8 | X5: =SUMPRODUCT(--(B5:O5=B$21:O$21)) -> 7 | Y5: =SUMPRODUCT(--(B5:O5=B$20:O$20)) -> 6 | Z5: =SUMPRODUCT(--(B5:O5=B$19:O$19)) -> 6 | AA5: =SUMPRODUCT(--(B5:O5=B$18:O$18)) -> 5 | AB5: =SUMPRODUCT(--(B5:O5=B$17:O$17)) -> 8 | AC5: =SUMPRODUCT(--(B5:O5=B$16:O$16)) -> 4 | AD5: =SUMPRODUCT(--(B5:O5=B$15:O$15)) -> 4 | AE5: =SUMPRODUCT(--(B5:O5=B$14:O$14)) -> 7 | AF5: =SUMPRODUCT(--(B5:O5=B$13:O$13)) -> 5 | AG5: =SUMPRODUCT(--(B5:O5=B$12:O$12)) -> 6 | AH5: =SUMPRODUCT(--(B5:O5=B$11:O$11)) -> 6 | AI5: =SUMPRODUCT(--(B5:O5=B$10:O$10)) -> 4 | AJ5: =SUMPRODUCT(--(B5:O5=B$9:O$9)) -> 4 | AK5: =SUMPRODUCT(--(B5:O5=B$8:O$8)) -> 3 | AL5: =SUMPRODUCT(--(B5:O5=B$7:O$7)) -> 4 | AM5: =SUMPRODUCT(--(B5:O5=B$6:O$6)) -> 7 | AR5: 4 | AS5: =COUNTIFS(T$2:AP$24,AR5) -> 50
B6: ['X' | C6: '1' | D6: '1' | E6: '1' | F6: '2' | G6: '1' | H6: 'X' | I6: '2' | J6: '1' | K6: '2' | L6: '2' | M6: '2' | N6: '1' | O6: '1'] | P6: =COUNTIF(B6:O6,A$26)+COUNTIF(B6:O6,A$36)+COUNTIF(B6:O6,A$39) -> 7 | Q6: =COUNTIF(B6:O6,A$27)+COUNTIF(B6:O6,A$37)+COUNTIF(B6:O6,A$40) -> 2 | R6: =COUNTIF(B6:O6,A$28)+COUNTIF(B6:O6,A$38)+COUNTIF(B6:O6,A$41) -> 5 | S6: =SUM(P6:R6) -> 14 | T6: =SUMPRODUCT(--(B6:O6=B$25:O$25)) -> 5 | U6: =SUMPRODUCT(--(B6:O6=B$24:O$24)) -> 8 | V6: =SUMPRODUCT(--(B6:O6=B$23:O$23)) -> 8 | W6: =SUMPRODUCT(--(B6:O6=B$22:O$22)) -> 7 | X6: =SUMPRODUCT(--(B6:O6=B$21:O$21)) -> 6 | Y6: =SUMPRODUCT(--(B6:O6=B$20:O$20)) -> 8 | Z6: =SUMPRODUCT(--(B6:O6=B$19:O$19)) -> 5 | AA6: =SUMPRODUCT(--(B6:O6=B$18:O$18)) -> 8 | AB6: =SUMPRODUCT(--(B6:O6=B$17:O$17)) -> 6 | AC6: =SUMPRODUCT(--(B6:O6=B$16:O$16)) -> 3 | AD6: =SUMPRODUCT(--(B6:O6=B$15:O$15)) -> 6 | AE6: =SUMPRODUCT(--(B6:O6=B$14:O$14)) -> 5 | AF6: =SUMPRODUCT(--(B6:O6=B$13:O$13)) -> 4 | AG6: =SUMPRODUCT(--(B6:O6=B$12:O$12)) -> 5 | AH6: =SUMPRODUCT(--(B6:O6=B$11:O$11)) -> 3 | AI6: =SUMPRODUCT(--(B6:O6=B$10:O$10)) -> 5 | AJ6: =SUMPRODUCT(--(B6:O6=B$9:O$9)) -> 6 | AK6: =SUMPRODUCT(--(B6:O6=B$8:O$8)) -> 7 | AL6: =SUMPRODUCT(--(B6:O6=B$7:O$7)) -> 3 | AR6: 5 | AS6: =COUNTIFS(T$2:AP$24,AR6) -> 66
B7: ['X' | C7: 'X' | D7: 'X' | E7: '2' | F7: '1' | G7: 'X' | H7: '2' | I7: 'X' | J7: '2' | K7: '1' | L7: '1' | M7: '2' | N7: '1' | O7: '2'] | P7: =COUNTIF(B7:O7,A$26)+COUNTIF(B7:O7,A$36)+COUNTIF(B7:O7,A$39) -> 4 | Q7: =COUNTIF(B7:O7,A$27)+COUNTIF(B7:O7,A$37)+COUNTIF(B7:O7,A$40) -> 5 | R7: =COUNTIF(B7:O7,A$28)+COUNTIF(B7:O7,A$38)+COUNTIF(B7:O7,A$41) -> 5 | S7: =SUM(P7:R7) -> 14 | T7: =SUMPRODUCT(--(B7:O7=B$25:O$25)) -> 4 | U7: =SUMPRODUCT(--(B7:O7=B$24:O$24)) -> 3 | V7: =SUMPRODUCT(--(B7:O7=B$23:O$23)) -> 3 | W7: =SUMPRODUCT(--(B7:O7=B$22:O$22)) -> 2 | X7: =SUMPRODUCT(--(B7:O7=B$21:O$21)) -> 6 | Y7: =SUMPRODUCT(--(B7:O7=B$20:O$20)) -> 3 | Z7: =SUMPRODUCT(--(B7:O7=B$19:O$19)) -> 4 | AA7: =SUMPRODUCT(--(B7:O7=B$18:O$18)) -> 3 | AB7: =SUMPRODUCT(--(B7:O7=B$17:O$17)) -> 2 | AC7: =SUMPRODUCT(--(B7:O7=B$16:O$16)) -> 5 | AD7: =SUMPRODUCT(--(B7:O7=B$15:O$15)) -> 6 | AE7: =SUMPRODUCT(--(B7:O7=B$14:O$14)) -> 7 | AF7: =SUMPRODUCT(--(B7:O7=B$13:O$13)) -> 5 | AG7: =SUMPRODUCT(--(B7:O7=B$12:O$12)) -> 2 | AH7: =SUMPRODUCT(--(B7:O7=B$11:O$11)) -> 5 | AI7: =SUMPRODUCT(--(B7:O7=B$10:O$10)) -> 2 | AJ7: =SUMPRODUCT(--(B7:O7=B$9:O$9)) -> 2 | AK7: =SUMPRODUCT(--(B7:O7=B$8:O$8)) -> 7 | AR7: 6 | AS7: =COUNTIFS(T$2:AP$24,AR7) -> 47
B8: ['X' | C8: '1' | D8: 'X' | E8: '1' | F8: '1' | G8: 'X' | H8: '1' | I8: '1' | J8: '2' | K8: '2' | L8: '2' | M8: '2' | N8: '1' | O8: 'X'] | P8: =COUNTIF(B8:O8,A$26)+COUNTIF(B8:O8,A$36)+COUNTIF(B8:O8,A$39) -> 6 | Q8: =COUNTIF(B8:O8,A$27)+COUNTIF(B8:O8,A$37)+COUNTIF(B8:O8,A$40) -> 4 | R8: =COUNTIF(B8:O8,A$28)+COUNTIF(B8:O8,A$38)+COUNTIF(B8:O8,A$41) -> 4 | S8: =SUM(P8:R8) -> 14 | T8: =SUMPRODUCT(--(B8:O8=B$25:O$25)) -> 5 | U8: =SUMPRODUCT(--(B8:O8=B$24:O$24)) -> 3 | V8: =SUMPRODUCT(--(B8:O8=B$23:O$23)) -> 2 | W8: =SUMPRODUCT(--(B8:O8=B$22:O$22)) -> 3 | X8: =SUMPRODUCT(--(B8:O8=B$21:O$21)) -> 4 | Y8: =SUMPRODUCT(--(B8:O8=B$20:O$20)) -> 4 | Z8: =SUMPRODUCT(--(B8:O8=B$19:O$19)) -> 8 | AA8: =SUMPRODUCT(--(B8:O8=B$18:O$18)) -> 5 | AB8: =SUMPRODUCT(--(B8:O8=B$17:O$17)) -> 5 | AC8: =SUMPRODUCT(--(B8:O8=B$16:O$16)) -> 4 | AD8: =SUMPRODUCT(--(B8:O8=B$15:O$15)) -> 6 | AE8: =SUMPRODUCT(--(B8:O8=B$14:O$14)) -> 4 | AF8: =SUMPRODUCT(--(B8:O8=B$13:O$13)) -> 4 | AG8: =SUMPRODUCT(--(B8:O8=B$12:O$12)) -> 5 | AH8: =SUMPRODUCT(--(B8:O8=B$11:O$11)) -> 2 | AI8: =SUMPRODUCT(--(B8:O8=B$10:O$10)) -> 5 | AJ8: =SUMPRODUCT(--(B8:O8=B$9:O$9)) -> 4 | AR8: 7 | AS8: =COUNTIFS(T$2:AP$24,AR8) -> 39
B9: ['X' | C9: '1' | D9: '2' | E9: 'X' | F9: '1' | G9: '1' | H9: '1' | I9: '2' | J9: '1' | K9: 'X' | L9: 'X' | M9: '1' | N9: '2' | O9: '1'] | P9: =COUNTIF(B9:O9,A$26)+COUNTIF(B9:O9,A$36)+COUNTIF(B9:O9,A$39) -> 7 | Q9: =COUNTIF(B9:O9,A$27)+COUNTIF(B9:O9,A$37)+COUNTIF(B9:O9,A$40) -> 4 | R9: =COUNTIF(B9:O9,A$28)+COUNTIF(B9:O9,A$38)+COUNTIF(B9:O9,A$41) -> 3 | S9: =SUM(P9:R9) -> 14 | T9: =SUMPRODUCT(--(B9:O9=B$25:O$25)) -> 3 | U9: =SUMPRODUCT(--(B9:O9=B$24:O$24)) -> 5 | V9: =SUMPRODUCT(--(B9:O9=B$23:O$23)) -> 8 | W9: =SUMPRODUCT(--(B9:O9=B$22:O$22)) -> 5 | X9: =SUMPRODUCT(--(B9:O9=B$21:O$21)) -> 7 | Y9: =SUMPRODUCT(--(B9:O9=B$20:O$20)) -> 4 | Z9: =SUMPRODUCT(--(B9:O9=B$19:O$19)) -> 5 | AA9: =SUMPRODUCT(--(B9:O9=B$18:O$18)) -> 5 | AB9: =SUMPRODUCT(--(B9:O9=B$17:O$17)) -> 7 | AC9: =SUMPRODUCT(--(B9:O9=B$16:O$16)) -> 5 | AD9: =SUMPRODUCT(--(B9:O9=B$15:O$15)) -> 5 | AE9: =SUMPRODUCT(--(B9:O9=B$14:O$14)) -> 4 | AF9: =SUMPRODUCT(--(B9:O9=B$13:O$13)) -> 5 | AG9: =SUMPRODUCT(--(B9:O9=B$12:O$12)) -> 4 | AH9: =SUMPRODUCT(--(B9:O9=B$11:O$11)) -> 5 | AI9: =SUMPRODUCT(--(B9:O9=B$10:O$10)) -> 6 | AR9: 8 | AS9: =COUNTIFS(T$2:AP$24,AR9) -> 25
B10: ['1' | C10: '2' | D10: '1' | E10: 'X' | F10: 'X' | G10: 'X' | H10: '1' | I10: '1' | J10: '1' | K10: 'X' | L10: '2' | M10: '1' | N10: '1' | O10: '1'] | P10: =COUNTIF(B10:O10,A$26)+COUNTIF(B10:O10,A$36)+COUNTIF(B10:O10,A$39) -> 8 | Q10: =COUNTIF(B10:O10,A$27)+COUNTIF(B10:O10,A$37)+COUNTIF(B10:O10,A$40) -> 4 | R10: =COUNTIF(B10:O10,A$28)+COUNTIF(B10:O10,A$38)+COUNTIF(B10:O10,A$41) -> 2 | S10: =SUM(P10:R10) -> 14 | T10: =SUMPRODUCT(--(B10:O10=B$25:O$25)) -> 3 | U10: =SUMPRODUCT(--(B10:O10=B$24:O$24)) -> 7 | V10: =SUMPRODUCT(--(B10:O10=B$23:O$23)) -> 8 | W10: =SUMPRODUCT(--(B10:O10=B$22:O$22)) -> 6 | X10: =SUMPRODUCT(--(B10:O10=B$21:O$21)) -> 6 | Y10: =SUMPRODUCT(--(B10:O10=B$20:O$20)) -> 5 | Z10: =SUMPRODUCT(--(B10:O10=B$19:O$19)) -> 6 | AA10: =SUMPRODUCT(--(B10:O10=B$18:O$18)) -> 4 | AB10: =SUMPRODUCT(--(B10:O10=B$17:O$17)) -> 4 | AC10: =SUMPRODUCT(--(B10:O10=B$16:O$16)) -> 8 | AD10: =SUMPRODUCT(--(B10:O10=B$15:O$15)) -> 4 | AE10: =SUMPRODUCT(--(B10:O10=B$14:O$14)) -> 7 | AF10: =SUMPRODUCT(--(B10:O10=B$13:O$13)) -> 7 | AG10: =SUMPRODUCT(--(B10:O10=B$12:O$12)) -> 9 | AH10: =SUMPRODUCT(--(B10:O10=B$11:O$11)) -> 5 | AR10: 9 | AS10: =COUNTIFS(T$2:AP$24,AR10) -> 10
B11: ['X' | C11: '2' | D11: '1' | E11: 'X' | F11: '2' | G11: '2' | H11: '1' | I11: 'X' | J11: 'X' | K11: '1' | L11: '1' | M11: '1' | N11: '2' | O11: '2'] | P11: =COUNTIF(B11:O11,A$26)+COUNTIF(B11:O11,A$36)+COUNTIF(B11:O11,A$39) -> 5 | Q11: =COUNTIF(B11:O11,A$27)+COUNTIF(B11:O11,A$37)+COUNTIF(B11:O11,A$40) -> 4 | R11: =COUNTIF(B11:O11,A$28)+COUNTIF(B11:O11,A$38)+COUNTIF(B11:O11,A$41) -> 5 | S11: =SUM(P11:R11) -> 14 | T11: =SUMPRODUCT(--(B11:O11=B$25:O$25)) -> 2 | U11: =SUMPRODUCT(--(B11:O11=B$24:O$24)) -> 4 | V11: =SUMPRODUCT(--(B11:O11=B$23:O$23)) -> 5 | W11: =SUMPRODUCT(--(B11:O11=B$22:O$22)) -> 6 | X11: =SUMPRODUCT(--(B11:O11=B$21:O$21)) -> 5 | Y11: =SUMPRODUCT(--(B11:O11=B$20:O$20)) -> 5 | Z11: =SUMPRODUCT(--(B11:O11=B$19:O$19)) -> 4 | AA11: =SUMPRODUCT(--(B11:O11=B$18:O$18)) -> 4 | AB11: =SUMPRODUCT(--(B11:O11=B$17:O$17)) -> 3 | AC11: =SUMPRODUCT(--(B11:O11=B$16:O$16)) -> 6 | AD11: =SUMPRODUCT(--(B11:O11=B$15:O$15)) -> 6 | AE11: =SUMPRODUCT(--(B11:O11=B$14:O$14)) -> 6 | AF11: =SUMPRODUCT(--(B11:O11=B$13:O$13)) -> 5 | AG11: =SUMPRODUCT(--(B11:O11=B$12:O$12)) -> 5 | AR11: 10 | AS11: =COUNTIFS(T$2:AP$24,AR11) -> 2
B12: ['2' | C12: '2' | D12: '1' | E12: '1' | F12: 'X' | G12: 'X' | H12: '1' | I12: '1' | J12: '1' | K12: '2' | L12: '1' | M12: '1' | N12: 'X' | O12: '1'] | P12: =COUNTIF(B12:O12,A$26)+COUNTIF(B12:O12,A$36)+COUNTIF(B12:O12,A$39) -> 8 | Q12: =COUNTIF(B12:O12,A$27)+COUNTIF(B12:O12,A$37)+COUNTIF(B12:O12,A$40) -> 3 | R12: =COUNTIF(B12:O12,A$28)+COUNTIF(B12:O12,A$38)+COUNTIF(B12:O12,A$41) -> 3 | S12: =SUM(P12:R12) -> 14 | T12: =SUMPRODUCT(--(B12:O12=B$25:O$25)) -> 3 | U12: =SUMPRODUCT(--(B12:O12=B$24:O$24)) -> 7 | V12: =SUMPRODUCT(--(B12:O12=B$23:O$23)) -> 5 | W12: =SUMPRODUCT(--(B12:O12=B$22:O$22)) -> 9 | X12: =SUMPRODUCT(--(B12:O12=B$21:O$21)) -> 4 | Y12: =SUMPRODUCT(--(B12:O12=B$20:O$20)) -> 8 | Z12: =SUMPRODUCT(--(B12:O12=B$19:O$19)) -> 9 | AA12: =SUMPRODUCT(--(B12:O12=B$18:O$18)) -> 6 | AB12: =SUMPRODUCT(--(B12:O12=B$17:O$17)) -> 7 | AC12: =SUMPRODUCT(--(B12:O12=B$16:O$16)) -> 5 | AD12: =SUMPRODUCT(--(B12:O12=B$15:O$15)) -> 4 | AE12: =SUMPRODUCT(--(B12:O12=B$14:O$14)) -> 5 | AF12: =SUMPRODUCT(--(B12:O12=B$13:O$13)) -> 5 | AR12: 11 | AS12: =COUNTIFS(T$2:AP$24,AR12) -> 2
B13: ['1' | C13: '1' | D13: '1' | E13: '2' | F13: '1' | G13: '2' | H13: '2' | I13: '1' | J13: 'X' | K13: 'X' | L13: '1' | M13: '1' | N13: '1' | O13: '1'] | P13: =COUNTIF(B13:O13,A$26)+COUNTIF(B13:O13,A$36)+COUNTIF(B13:O13,A$39) -> 9 | Q13: =COUNTIF(B13:O13,A$27)+COUNTIF(B13:O13,A$37)+COUNTIF(B13:O13,A$40) -> 2 | R13: =COUNTIF(B13:O13,A$28)+COUNTIF(B13:O13,A$38)+COUNTIF(B13:O13,A$41) -> 3 | S13: =SUM(P13:R13) -> 14 | T13: =SUMPRODUCT(--(B13:O13=B$25:O$25)) -> 6 | U13: =SUMPRODUCT(--(B13:O13=B$24:O$24)) -> 9 | V13: =SUMPRODUCT(--(B13:O13=B$23:O$23)) -> 9 | W13: =SUMPRODUCT(--(B13:O13=B$22:O$22)) -> 6 | X13: =SUMPRODUCT(--(B13:O13=B$21:O$21)) -> 9 | Y13: =SUMPRODUCT(--(B13:O13=B$20:O$20)) -> 6 | Z13: =SUMPRODUCT(--(B13:O13=B$19:O$19)) -> 5 | AA13: =SUMPRODUCT(--(B13:O13=B$18:O$18)) -> 5 | AB13: =SUMPRODUCT(--(B13:O13=B$17:O$17)) -> 5 | AC13: =SUMPRODUCT(--(B13:O13=B$16:O$16)) -> 8 | AD13: =SUMPRODUCT(--(B13:O13=B$15:O$15)) -> 7 | AE13: =SUMPRODUCT(--(B13:O13=B$14:O$14)) -> 8 | AR13: 12 | AS13: =COUNTIFS(T$2:AP$24,AR13) -> 0
B14: ['1' | C14: '2' | D14: '1' | E14: 'X' | F14: '1' | G14: 'X' | H14: '2' | I14: '2' | J14: 'X' | K14: '1' | L14: '1' | M14: '2' | N14: '1' | O14: '1'] | P14: =COUNTIF(B14:O14,A$26)+COUNTIF(B14:O14,A$36)+COUNTIF(B14:O14,A$39) -> 7 | Q14: =COUNTIF(B14:O14,A$27)+COUNTIF(B14:O14,A$37)+COUNTIF(B14:O14,A$40) -> 3 | R14: =COUNTIF(B14:O14,A$28)+COUNTIF(B14:O14,A$38)+COUNTIF(B14:O14,A$41) -> 4 | S14: =SUM(P14:R14) -> 14 | T14: =SUMPRODUCT(--(B14:O14=B$25:O$25)) -> 4 | U14: =SUMPRODUCT(--(B14:O14=B$24:O$24)) -> 6 | V14: =SUMPRODUCT(--(B14:O14=B$23:O$23)) -> 8 | W14: =SUMPRODUCT(--(B14:O14=B$22:O$22)) -> 5 | X14: =SUMPRODUCT(--(B14:O14=B$21:O$21)) -> 10 | Y14: =SUMPRODUCT(--(B14:O14=B$20:O$20)) -> 4 | Z14: =SUMPRODUCT(--(B14:O14=B$19:O$19)) -> 4 | AA14: =SUMPRODUCT(--(B14:O14=B$18:O$18)) -> 2 | AB14: =SUMPRODUCT(--(B14:O14=B$17:O$17)) -> 4 | AC14: =SUMPRODUCT(--(B14:O14=B$16:O$16)) -> 5 | AD14: =SUMPRODUCT(--(B14:O14=B$15:O$15)) -> 6 | AR14: 13 | AS14: =COUNTIFS(T$2:AP$24,AR14) -> 0
B15: ['X' | C15: '1' | D15: '1' | E15: 'X' | F15: '1' | G15: '2' | H15: '2' | I15: 'X' | J15: '1' | K15: '2' | L15: '1' | M15: 'X' | N15: '1' | O15: 'X'] | P15: =COUNTIF(B15:O15,A$26)+COUNTIF(B15:O15,A$36)+COUNTIF(B15:O15,A$39) -> 6 | Q15: =COUNTIF(B15:O15,A$27)+COUNTIF(B15:O15,A$37)+COUNTIF(B15:O15,A$40) -> 5 | R15: =COUNTIF(B15:O15,A$28)+COUNTIF(B15:O15,A$38)+COUNTIF(B15:O15,A$41) -> 3 | S15: =SUM(P15:R15) -> 14 | T15: =SUMPRODUCT(--(B15:O15=B$25:O$25)) -> 7 | U15: =SUMPRODUCT(--(B15:O15=B$24:O$24)) -> 7 | V15: =SUMPRODUCT(--(B15:O15=B$23:O$23)) -> 7 | W15: =SUMPRODUCT(--(B15:O15=B$22:O$22)) -> 5 | X15: =SUMPRODUCT(--(B15:O15=B$21:O$21)) -> 7 | Y15: =SUMPRODUCT(--(B15:O15=B$20:O$20)) -> 7 | Z15: =SUMPRODUCT(--(B15:O15=B$19:O$19)) -> 6 | AA15: =SUMPRODUCT(--(B15:O15=B$18:O$18)) -> 6 | AB15: =SUMPRODUCT(--(B15:O15=B$17:O$17)) -> 7 | AC15: =SUMPRODUCT(--(B15:O15=B$16:O$16)) -> 4 | AR15: 14 | AS15: =COUNTIFS(T$2:AP$24,AR15) -> 0
B16: ['1' | C16: '1' | D16: '1' | E16: '2' | F16: 'X' | G16: 'X' | H16: '1' | I16: 'X' | J16: 'X' | K16: 'X' | L16: 'X' | M16: '1' | N16: '1' | O16: '2'] | P16: =COUNTIF(B16:O16,A$26)+COUNTIF(B16:O16,A$36)+COUNTIF(B16:O16,A$39) -> 6 | Q16: =COUNTIF(B16:O16,A$27)+COUNTIF(B16:O16,A$37)+COUNTIF(B16:O16,A$40) -> 6 | R16: =COUNTIF(B16:O16,A$28)+COUNTIF(B16:O16,A$38)+COUNTIF(B16:O16,A$41) -> 2 | S16: =SUM(P16:R16) -> 14 | T16: =SUMPRODUCT(--(B16:O16=B$25:O$25)) -> 5 | U16: =SUMPRODUCT(--(B16:O16=B$24:O$24)) -> 7 | V16: =SUMPRODUCT(--(B16:O16=B$23:O$23)) -> 6 | W16: =SUMPRODUCT(--(B16:O16=B$22:O$22)) -> 4 | X16: =SUMPRODUCT(--(B16:O16=B$21:O$21)) -> 5 | Y16: =SUMPRODUCT(--(B16:O16=B$20:O$20)) -> 6 | Z16: =SUMPRODUCT(--(B16:O16=B$19:O$19)) -> 3 | AA16: =SUMPRODUCT(--(B16:O16=B$18:O$18)) -> 5 | AB16: =SUMPRODUCT(--(B16:O16=B$17:O$17)) -> 4
B17: ['2' | C17: '1' | D17: '1' | E17: '1' | F17: '1' | G17: '1' | H17: '1' | I17: '2' | J17: '1' | K17: 'X' | L17: '1' | M17: 'X' | N17: 'X' | O17: 'X'] | P17: =COUNTIF(B17:O17,A$26)+COUNTIF(B17:O17,A$36)+COUNTIF(B17:O17,A$39) -> 8 | Q17: =COUNTIF(B17:O17,A$27)+COUNTIF(B17:O17,A$37)+COUNTIF(B17:O17,A$40) -> 4 | R17: =COUNTIF(B17:O17,A$28)+COUNTIF(B17:O17,A$38)+COUNTIF(B17:O17,A$41) -> 2 | S17: =SUM(P17:R17) -> 14 | T17: =SUMPRODUCT(--(B17:O17=B$25:O$25)) -> 5 | U17: =SUMPRODUCT(--(B17:O17=B$24:O$24)) -> 5 | V17: =SUMPRODUCT(--(B17:O17=B$23:O$23)) -> 7 | W17: =SUMPRODUCT(--(B17:O17=B$22:O$22)) -> 7 | X17: =SUMPRODUCT(--(B17:O17=B$21:O$21)) -> 6 | Y17: =SUMPRODUCT(--(B17:O17=B$20:O$20)) -> 7 | Z17: =SUMPRODUCT(--(B17:O17=B$19:O$19)) -> 8 | AA17: =SUMPRODUCT(--(B17:O17=B$18:O$18)) -> 4
B18: ['2' | C18: '1' | D18: 'X' | E18: '1' | F18: '2' | G18: '2' | H18: 'X' | I18: 'X' | J18: '1' | K18: '2' | L18: 'X' | M18: '1' | N18: '1' | O18: '1'] | P18: =COUNTIF(B18:O18,A$26)+COUNTIF(B18:O18,A$36)+COUNTIF(B18:O18,A$39) -> 6 | Q18: =COUNTIF(B18:O18,A$27)+COUNTIF(B18:O18,A$37)+COUNTIF(B18:O18,A$40) -> 4 | R18: =COUNTIF(B18:O18,A$28)+COUNTIF(B18:O18,A$38)+COUNTIF(B18:O18,A$41) -> 4 | S18: =SUM(P18:R18) -> 14 | T18: =SUMPRODUCT(--(B18:O18=B$25:O$25)) -> 5 | U18: =SUMPRODUCT(--(B18:O18=B$24:O$24)) -> 8 | V18: =SUMPRODUCT(--(B18:O18=B$23:O$23)) -> 6 | W18: =SUMPRODUCT(--(B18:O18=B$22:O$22)) -> 7 | X18: =SUMPRODUCT(--(B18:O18=B$21:O$21)) -> 4 | Y18: =SUMPRODUCT(--(B18:O18=B$20:O$20)) -> 9 | Z18: =SUMPRODUCT(--(B18:O18=B$19:O$19)) -> 7
B19: ['2' | C19: '2' | D19: 'X' | E19: '1' | F19: '1' | G19: '1' | H19: '1' | I19: '1' | J19: '1' | K19: '2' | L19: '1' | M19: '1' | N19: '1' | O19: 'X'] | P19: =COUNTIF(B19:O19,A$26)+COUNTIF(B19:O19,A$36)+COUNTIF(B19:O19,A$39) -> 9 | Q19: =COUNTIF(B19:O19,A$27)+COUNTIF(B19:O19,A$37)+COUNTIF(B19:O19,A$40) -> 2 | R19: =COUNTIF(B19:O19,A$28)+COUNTIF(B19:O19,A$38)+COUNTIF(B19:O19,A$41) -> 3 | S19: =SUM(P19:R19) -> 14 | T19: =SUMPRODUCT(--(B19:O19=B$25:O$25)) -> 4 | U19: =SUMPRODUCT(--(B19:O19=B$24:O$24)) -> 5 | V19: =SUMPRODUCT(--(B19:O19=B$23:O$23)) -> 5 | W19: =SUMPRODUCT(--(B19:O19=B$22:O$22)) -> 6 | X19: =SUMPRODUCT(--(B19:O19=B$21:O$21)) -> 5 | Y19: =SUMPRODUCT(--(B19:O19=B$20:O$20)) -> 7
